Workbook

Sheet BEHAVIOURABILITY
B1: Decision Making | C1: Self-Management | D1: Engagement
A2: T1 Rionoscere l'episodio | B2: K&S | D2: MOT
A3: T2 Passi immediati | B3: K&S | C3: SE | D3: MOT
A4: T3 Documentare in sicurezza | B4: K&S, PC | C4: SE | D4: MOT
A5: T4 Segnalare (anche anonimo) | B5: K&S, PC | C5: SE | D5: MOT
A6: T5 Contattare referenti/servizi | B6: K&S | C6: SE | D6: MOT
A7: T6 Supporto alla persona | B7: K&S | C7: SE | D7: MOT
A8: T7 Follow-up del caso | B8: K&S, PC | C8: SE | D8: MOT
A9: T8 Aggregare per prevenzi. | B9: K&S, PC | C9: SE | D9: MOT
A11: SE = Self-Efficacy
A12: K&S = Knowledge & Skills
A13: PC = Personal Control
A14: MOT = Motivation

Sheet Quest.Utente1
B1: Self Efficacy | C1: Scarso | D1: Sufficiente | E1: Buono | F1: Molto Buono | G1: Eccellente | H1: Valore
A2: T2_SE1 | B2: Come valuti il tuo livello di disinvoltura nel loggare velocemente il tuo stato d'animo? | C2: FALSE | D2: FALSE | E2: FALSE | F2: FALSE | G2: TRUE | H2: =IF(C2=TRUE,1,0) + IF(D2=TRUE,2,0) + IF(E2=TRUE,3,0) + IF(F2=TRUE,4,0) + IF(G2=TRUE,5,0) -> 5
A3: T2_SE2 | B3: Come valuti la tua abilità nell'usare gli strumenti forniti (scala, emoji, tag) per loggare l'umore come intendi tu? | C3: FALSE | D3: FALSE | E3: FALSE | F3: FALSE | G3: TRUE | H3: =IF(C3=TRUE,1,0) + IF(D3=TRUE,2,0) + IF(E3=TRUE,3,0) + IF(F3=TRUE,4,0) + IF(G3=TRUE,5,0) -> 5
A4: T3_SE1 | B4: Come valuti il tuo livello di disinvoltura nell'usare la funzione di scrittura guidata per riflettere? | C4: FALSE | D4: FALSE | E4: FALSE | F4: TRUE | G4: FALSE | H4: =IF(C4=TRUE,1,0) + IF(D4=TRUE,2,0) + IF(E4=TRUE,3,0) + IF(F4=TRUE,4,0) + IF(G4=TRUE,5,0) -> 4
A5: T3_SE2 | B5: Come valuti la tua abilità nell'esprimere i tuoi pensieri e sentimenti rispondendo ai prompt proposti? | C5: FALSE | D5: FALSE | E5: FALSE | F5: FALSE | G5: TRUE | H5: =IF(C5=TRUE,1,0) + IF(D5=TRUE,2,0) + IF(E5=TRUE,3,0) + IF(F5=TRUE,4,0) + IF(G5=TRUE,5,0) -> 5
A6: T4_SE1 | B6: Come valuti il tuo livello di disinvoltura nello scrivere liberamente nel diario dell'app? | C6: FALSE | D6: FALSE | E6: FALSE | F6: TRUE | G6: FALSE | H6: =IF(C6=TRUE,1,0) + IF(D6=TRUE,2,0) + IF(E6=TRUE,3,0) + IF(F6=TRUE,4,0) + IF(G6=TRUE,5,0) -> 4
A7: T4_SE2 | B7: Come valuti la tua abilità nell'esprimere liberamente ciò che senti o pensi usando la funzione diario? | C7: FALSE | D7: FALSE | E7: FALSE | F7: FALSE | G7: TRUE | H7: =IF(C7=TRUE,1,0) + IF(D7=TRUE,2,0) + IF(E7=TRUE,3,0) + IF(F7=TRUE,4,0) + IF(G7=TRUE,5,0) -> 5
A8: T5_SE1 | B8: Come valuti il tuo livello di disinvoltura nel consultare le tue registrazioni passate (umore e note)? | C8: FALSE | D8: FALSE | E8: FALSE | F8: FALSE | G8: TRUE | H8: =IF(C8=TRUE,1,0) + IF(D8=TRUE,2,0) + IF(E8=TRUE,3,0) + IF(F8=TRUE,4,0) + IF(G8=TRUE,5,0) -> 5
A9: T5_SE2 | B9: Come valuti la tua abilità nel trovare specifiche informazioni o note all'interno delle tue registrazioni passate? | C9: FALSE | D9: FALSE | E9: FALSE | F9: FALSE | G9: TRUE | H9: =IF(C9=TRUE,1,0) + IF(D9=TRUE,2,0) + IF(E9=TRUE,3,0) + IF(F9=TRUE,4,0) + IF(G9=TRUE,5,0) -> 5
A10: T6_SE1 | B10: Come valuti il tuo livello di disinvoltura nell'accedere e guardare i grafici e le sintesi dei tuoi dati? | C10: FALSE | D10: FALSE | E10: FALSE | F10: FALSE | G10: TRUE | H10: =IF(C10=TRUE,1,0) + IF(D10=TRUE,2,0) + IF(E10=TRUE,3,0) + IF(F10=TRUE,4,0) + IF(G10=TRUE,5,0) -> 5
A11: T6_SE2 | B11: Come valuti la tua abilità nell'interpretare correttamente le informazioni presentate nei grafici e nelle sintesi? | C11: FALSE | D11: FALSE | E11: FALSE | F11: FALSE | G11: TRUE | H11: =IF(C11=TRUE,1,0) + IF(D11=TRUE,2,0) + IF(E11=TRUE,3,0) + IF(F11=TRUE,4,0) + IF(G11=TRUE,5,0) -> 5
A12: T7_SE1 | B12: Come valuti il tuo livello di disinvoltura nell'utilizzare le brevi pratiche guidate (es. respirazione, mindfulness)? | C12: FALSE | D12: FALSE | E12: FALSE | F12: FALSE | G12: TRUE | H12: =IF(C12=TRUE,1,0) + IF(D12=TRUE,2,0) + IF(E12=TRUE,3,0) + IF(F12=TRUE,4,0) + IF(G12=TRUE,5,0) -> 5
A13: T7_SE2 | B13: Come valuti la tua abilità nel seguire le istruzioni e completare efficacemente gli esercizi brevi proposti? | C13: FALSE | D13: FALSE | E13: FALSE | F13: FALSE | G13: TRUE | H13: =IF(C13=TRUE,1,0) + IF(D13=TRUE,2,0) + IF(E13=TRUE,3,0) + IF(F13=TRUE,4,0) + IF(G13=TRUE,5,0) -> 5
B14: Knowledge&Skills | C14: FALSE | D14: FALSE | E14: FALSE | F14: FALSE | G14: FALSE | H14: =IF(C14=TRUE,1,0) + IF(D14=TRUE,2,0) + IF(E14=TRUE,3,0) + IF(F14=TRUE,4,0) + IF(G14=TRUE,5,0) -> 0
A15: T1_KS1 | B15: Che livello di conoscenza hai su come creare un account e impostare le preferenze iniziali nell'app? | C15: FALSE | D15: FALSE | E15: FALSE | F15: FALSE | G15: TRUE | H15: =IF(C15=TRUE,1,0) + IF(D15=TRUE,2,0) + IF(E15=TRUE,3,0) + IF(F15=TRUE,4,0) + IF(G15=TRUE,5,0) -> 5
A16: T1_KS2 | B16: Come valuti la tua competenza nel creare l'account e impostare le preferenze iniziali come desideri? | C16: FALSE | D16: FALSE | E16: TRUE | F16: FALSE | G16: FALSE | H16: =IF(C16=TRUE,1,0) + IF(D16=TRUE,2,0) + IF(E16=TRUE,3,0) + IF(F16=TRUE,4,0) + IF(G16=TRUE,5,0) -> 3
A17: T2_KS1 | B17: Che livello di conoscenza hai su come loggare velocemente il tuo stato d'animo usando gli strumenti dell'app (scala, emoji, tag)? | C17: FALSE | D17: FALSE | E17: FALSE | F17: FALSE | G17: TRUE | H17: =IF(C17=TRUE,1,0) + IF(D17=TRUE,2,0) + IF(E17=TRUE,3,0) + IF(F17=TRUE,4,0) + IF(G17=TRUE,5,0) -> 5
A18: T2_KS2 | B18: Come valuti la tua competenza nel loggare il tuo umore in modo rapido ed efficace? | C18: FALSE | D18: FALSE | E18: FALSE | F18: FALSE | G18: TRUE | H18: =IF(C18=TRUE,1,0) + IF(D18=TRUE,2,0) + IF(E18=TRUE,3,0) + IF(F18=TRUE,4,0) + IF(G18=TRUE,5,0) -> 5
A19: T3_KS1 | B19: Che livello di conoscenza hai su come funziona la funzione di scrittura guidata (rispondere a prompt/domande)? | C19: FALSE | D19: FALSE | E19: FALSE | F19: FALSE | G19: TRUE | H19: =IF(C19=TRUE,1,0) + IF(D19=TRUE,2,0) + IF(E19=TRUE,3,0) + IF(F19=TRUE,4,0) + IF(G19=TRUE,5,0) -> 5
A20: T3_KS2 | B20: Come valuti la tua competenza nel rispondere ai prompt proposti dall'app per riflettere? | C20: FALSE | D20: FALSE | E20: FALSE | F20: FALSE | G20: TRUE | H20: =IF(C20=TRUE,1,0) + IF(D20=TRUE,2,0) + IF(E20=TRUE,3,0) + IF(F20=TRUE,4,0) + IF(G20=TRUE,5,0) -> 5
A21: T4_KS1 | B21: Che livello di conoscenza hai su come usare la funzione diario per la scrittura libera? | C21: FALSE | D21: FALSE | E21: TRUE | F21: FALSE | G21: FALSE | H21: =IF(C21=TRUE,1,0) + IF(D21=TRUE,2,0) + IF(E21=TRUE,3,0) + IF(F21=TRUE,4,0) + IF(G21=TRUE,5,0) -> 3
A22: T4_KS2 | B22: Come valuti la tua competenza nello scrivere liberamente i tuoi pensieri, emozioni o eventi nel diario dell'app? | C22: FALSE | D22: FALSE | E22: FALSE | F22: FALSE | G22: TRUE | H22: =IF(C22=TRUE,1,0) + IF(D22=TRUE,2,0) + IF(E22=TRUE,3,0) + IF(F22=TRUE,4,0) + IF(G22=TRUE,5,0) -> 5
A23: T5_KS1 | B23: Che livello di conoscenza hai su come trovare e consultare le tue registrazioni passate (umore e note del diario)? | C23: FALSE | D23: FALSE | E23: FALSE | F23: FALSE | G23: TRUE | H23: =IF(C23=TRUE,1,0) + IF(D23=TRUE,2,0) + IF(E23=TRUE,3,0) + IF(F23=TRUE,4,0) + IF(G23=TRUE,5,0) -> 5
A24: T5_KS2 | B24: Come valuti la tua competenza nel navigare tra le tue registrazioni passate per ricordare o riflettere? | C24: FALSE | D24: FALSE | E24: FALSE | F24: FALSE | G24: TRUE | H24: =IF(C24=TRUE,1,0) + IF(D24=TRUE,2,0) + IF(E24=TRUE,3,0) + IF(F24=TRUE,4,0) + IF(G24=TRUE,5,0) -> 5
A25: T6_KS1 | B25: Che livello di conoscenza hai su come accedere e interpretare i grafici, calendari o sintesi sull'andamento dell'umore/temi? | C25: FALSE | D25: FALSE | E25: FALSE | F25: FALSE | G25: TRUE | H25: =IF(C25=TRUE,1,0) + IF(D25=TRUE,2,0) + IF(E25=TRUE,3,0) + IF(F25=TRUE,4,0) + IF(G25=TRUE,5,0) -> 5
A26: T6_KS2 | B26: Come valuti la tua competenza nell'utilizzare le visualizzazioni (grafici, ecc.) per capire i tuoi pattern o progressi? | C26: FALSE | D26: FALSE | E26: FALSE | F26: FALSE | G26: TRUE | H26: =IF(C26=TRUE,1,0) + IF(D26=TRUE,2,0) + IF(E26=TRUE,3,0) + IF(F26=TRUE,4,0) + IF(G26=TRUE,5,0) -> 5
... A28: T7_KS2 | B28: Come valuti la tua competenza nell'utilizzare efficacemente gli esercizi brevi per il tuo benessere? | C28: FALSE | D28: FALSE | E28: FALSE | F28: FALSE | G28: TRUE | H28: =IF(C28=TRUE,1,0) + IF(D28=TRUE,2,0) + IF(E28=TRUE,3,0) + IF(F28=TRUE,4,0) + IF(G28=TRUE,5,0) -> 5
B29: Personal Control | C29: FALSE | D29: FALSE | E29: FALSE | F29: FALSE | G29: FALSE | H29: =IF(C29=TRUE,1,0) + IF(D29=TRUE,2,0) + IF(E29=TRUE,3,0) + IF(F29=TRUE,4,0) + IF(G29=TRUE,5,0) -> 0
A30: T3_PC1 | B30: Come giudichi la tua abilità nel gestire eventuali difficoltà o blocchi mentre rispondi ai prompt di scrittura guidata? | C30: FALSE | D30: FALSE | E30: FALSE | F30: FALSE | G30: TRUE | H30: =IF(C30=TRUE,1,0) + IF(D30=TRUE,2,0) + IF(E30=TRUE,3,0) + IF(F30=TRUE,4,0) + IF(G30=TRUE,5,0) -> 5
A31: T3_PC2 | B31: Pensi di avere il controllo su come e quanto approfonditamente rispondere ai prompt di scrittura guidata? | C31: FALSE | D31: FALSE | E31: TRUE | F31: FALSE | G31: FALSE | H31: =IF(C31=TRUE,1,0) + IF(D31=TRUE,2,0) + IF(E31=TRUE,3,0) + IF(F31=TRUE,4,0) + IF(G31=TRUE,5,0) -> 3
A32: T4_PC1 | B32: Come giudichi la tua abilità nel superare un blocco dello scrittore o un'incertezza mentre usi la funzione di scrittura libera? | C32: FALSE | D32: FALSE | E32: FALSE | F32: FALSE | G32: TRUE | H32: =IF(C32=TRUE,1,0) + IF(D32=TRUE,2,0) + IF(E32=TRUE,3,0) + IF(F32=TRUE,4,0) + IF(G32=TRUE,5,0) -> 5
A33: T4_PC2 | B33: Pensi di avere il controllo su cosa, come e quando scrivere nel tuo diario libero? | C33: FALSE | D33: FALSE | E33: FALSE | F33: FALSE | G33: TRUE | H33: =IF(C33=TRUE,1,0) + IF(D33=TRUE,2,0) + IF(E33=TRUE,3,0) + IF(F33=TRUE,4,0) + IF(G33=TRUE,5,0) -> 5
A34: T7_PC1 | B34: Come giudichi la tua abilità nel gestire eventuali distrazioni o difficoltà durante l'esecuzione di un esercizio breve guidato? | C34: FALSE | D34: FALSE | E34: FALSE | F34: FALSE | G34: TRUE | H34: =IF(C34=TRUE,1,0) + IF(D34=TRUE,2,0) + IF(E34=TRUE,3,0) + IF(F34=TRUE,4,0) + IF(G34=TRUE,5,0) -> 5
A35: T7_PC2 | B35: Pensi di avere il controllo su quando e quale esercizio breve scegliere e avviare? | C35: FALSE | D35: FALSE | E35: FALSE | F35: FALSE | G35: TRUE | H35: =IF(C35=TRUE,1,0) + IF(D35=TRUE,2,0) + IF(E35=TRUE,3,0) + IF(F35=TRUE,4,0) + IF(G35=TRUE,5,0) -> 5
B36: Motivation | C36: FALSE | D36: FALSE | E36: FALSE | F36: FALSE | G36: FALSE | H36: =IF(C36=TRUE,1,0) + IF(D36=TRUE,2,0) + IF(E36=TRUE,3,0) + IF(F36=TRUE,4,0) + IF(G36=TRUE,5,0) -> 0
A37: T1_MOT1 | B37: Quanto è facile per te compiere i passi necessari per creare l'account e impostare le preferenze? | C37: FALSE | D37: FALSE | E37: FALSE | F37: FALSE | G37: TRUE | H37: =IF(C37=TRUE,1,0) + IF(D37=TRUE,2,0) + IF(E37=TRUE,3,0) + IF(F37=TRUE,4,0) + IF(G37=TRUE,5,0) -> 5
A38: T1_MOT2 | B38: Quanto è facile per te correggere eventuali errori durante la creazione dell'account o l'impostazione delle preferenze? | C38: FALSE | D38: FALSE | E38: FALSE | F38: FALSE | G38: TRUE | H38: =IF(C38=TRUE,1,0) + IF(D38=TRUE,2,0) + IF(E38=TRUE,3,0) + IF(F38=TRUE,4,0) + IF(G38=TRUE,5,0) -> 5
A39: T2_MOT1 | B39: Quanto è facile per te compiere le azioni per loggare velocemente il tuo umore? | C39: FALSE | D39: FALSE | E39: FALSE | F39: FALSE | G39: TRUE | H39: =IF(C39=TRUE,1,0) + IF(D39=TRUE,2,0) + IF(E39=TRUE,3,0) + IF(F39=TRUE,4,0) + IF(G39=TRUE,5,0) -> 5
A40: T2_MOT2 | B40: Quanto è facile per te correggere un errore se sbagli a loggare l'umore? | C40: FALSE | D40: FALSE | E40: FALSE | F40: FALSE | G40: TRUE | H40: =IF(C40=TRUE,1,0) + IF(D40=TRUE,2,0) + IF(E40=TRUE,3,0) + IF(F40=TRUE,4,0) + IF(G40=TRUE,5,0) -> 5
A41: T3_MOT1 | B41: Quanto è facile per te iniziare e completare una sessione di scrittura guidata quando proposto dall'app? | C41: FALSE | D41: FALSE | E41: FALSE | F41: FALSE | G41: TRUE | H41: =IF(C41=TRUE,1,0) + IF(D41=TRUE,2,0) + IF(E41=TRUE,3,0) + IF(F41=TRUE,4,0) + IF(G41=TRUE,5,0) -> 5
...

Sheet Quest.Utente2
B1: Self Efficacy | C1: Scarso | D1: Sufficiente | E1: Buono | F1: Molto Buono | G1: Eccellente | H1: Valore
A2: T2_SE1 | B2: Come valuti il tuo livello di disinvoltura nel loggare velocemente il tuo stato d'animo? | C2: FALSE | D2: FALSE | E2: FALSE | F2: FALSE | G2: TRUE | H2: =IF(C2=TRUE,1,0) + IF(D2=TRUE,2,0) + IF(E2=TRUE,3,0) + IF(F2=TRUE,4,0) + IF(G2=TRUE,5,0) -> 5
A3: T2_SE2 | B3: Come valuti la tua abilità nell'usare gli strumenti forniti (scala, emoji, tag) per loggare l'umore come intendi tu? | C3: FALSE | D3: FALSE | E3: FALSE | F3: FALSE | G3: TRUE | H3: =IF(C3=TRUE,1,0) + IF(D3=TRUE,2,0) + IF(E3=TRUE,3,0) + IF(F3=TRUE,4,0) + IF(G3=TRUE,5,0) -> 5
A4: T3_SE1 | B4: Come valuti il tuo livello di disinvoltura nell'usare la funzione di scrittura guidata per riflettere? | C4: FALSE | D4: FALSE | E4: FALSE | F4: FALSE | G4: TRUE | H4: =IF(C4=TRUE,1,0) + IF(D4=TRUE,2,0) + IF(E4=TRUE,3,0) + IF(F4=TRUE,4,0) + IF(G4=TRUE,5,0) -> 5
A5: T3_SE2 | B5: Come valuti la tua abilità nell'esprimere i tuoi pensieri e sentimenti rispondendo ai prompt proposti? | C5: FALSE | D5: FALSE | E5: FALSE | F5: FALSE | G5: TRUE | H5: =IF(C5=TRUE,1,0) + IF(D5=TRUE,2,0) + IF(E5=TRUE,3,0) + IF(F5=TRUE,4,0) + IF(G5=TRUE,5,0) -> 5
A6: T4_SE1 | B6: Come valuti il tuo livello di disinvoltura nello scrivere liberamente nel diario dell'app? | C6: FALSE | D6: FALSE | E6: FALSE | F6: FALSE | G6: TRUE | H6: =IF(C6=TRUE,1,0) + IF(D6=TRUE,2,0) + IF(E6=TRUE,3,0) + IF(F6=TRUE,4,0) + IF(G6=TRUE,5,0) -> 5
A7: T4_SE2 | B7: Come valuti la tua abilità nell'esprimere liberamente ciò che senti o pensi usando la funzione diario? | C7: FALSE | D7: FALSE | E7: FALSE | F7: FALSE | G7: TRUE | H7: =IF(C7=TRUE,1,0) + IF(D7=TRUE,2,0) + IF(E7=TRUE,3,0) + IF(F7=TRUE,4,0) + IF(G7=TRUE,5,0) -> 5
A8: T5_SE1 | B8: Come valuti il tuo livello di disinvoltura nel consultare le tue registrazioni passate (umore e note)? | C8: FALSE | D8: FALSE | E8: FALSE | F8: FALSE | G8: TRUE | H8: =IF(C8=TRUE,1,0) + IF(D8=TRUE,2,0) + IF(E8=TRUE,3,0) + IF(F8=TRUE,4,0) + IF(G8=TRUE,5,0) -> 5
A9: T5_SE2 | B9: Come valuti la tua abilità nel trovare specifiche informazioni o note all'interno delle tue registrazioni passate? | C9: FALSE | D9: FALSE | E9: FALSE | F9: FALSE | G9: TRUE | H9: =IF(C9=TRUE,1,0) + IF(D9=TRUE,2,0) + IF(E9=TRUE,3,0) + IF(F9=TRUE,4,0) + IF(G9=TRUE,5,0) -> 5
A10: T6_SE1 | B10: Come valuti il tuo livello di disinvoltura nell'accedere e guardare i grafici e le sintesi dei tuoi dati? | C10: FALSE | D10: FALSE | E10: FALSE | F10: FALSE | G10: TRUE | H10: =IF(C10=TRUE,1,0) + IF(D10=TRUE,2,0) + IF(E10=TRUE,3,0) + IF(F10=TRUE,4,0) + IF(G10=TRUE,5,0) -> 5
A11: T6_SE2 | B11: Come valuti la tua abilità nell'interpretare correttamente le informazioni presentate nei grafici e nelle sintesi? | C11: FALSE | D11: FALSE | E11: FALSE | F11: FALSE | G11: TRUE | H11: =IF(C11=TRUE,1,0) + IF(D11=TRUE,2,0) + IF(E11=TRUE,3,0) + IF(F11=TRUE,4,0) + IF(G11=TRUE,5,0) -> 5
A12: T7_SE1 | B12: Come valuti il tuo livello di disinvoltura nell'utilizzare le brevi pratiche guidate (es. respirazione, mindfulness)? | C12: FALSE | D12: FALSE | E12: FALSE | F12: FALSE | G12: TRUE | H12: =IF(C12=TRUE,1,0) + IF(D12=TRUE,2,0) + IF(E12=TRUE,3,0) + IF(F12=TRUE,4,0) + IF(G12=TRUE,5,0) -> 5
A13: T7_SE2 | B13: Come valuti la tua abilità nel seguire le istruzioni e completare efficacemente gli esercizi brevi proposti? | C13: FALSE | D13: FALSE | E13: FALSE | F13: FALSE | G13: TRUE | H13: =IF(C13=TRUE,1,0) + IF(D13=TRUE,2,0) + IF(E13=TRUE,3,0) + IF(F13=TRUE,4,0) + IF(G13=TRUE,5,0) -> 5
B14: Knowledge&Skills | C14: FALSE | D14: FALSE | E14: FALSE | F14: FALSE | G14: FALSE | H14: =IF(C14=TRUE,1,0) + IF(D14=TRUE,2,0) + IF(E14=TRUE,3,0) + IF(F14=TRUE,4,0) + IF(G14=TRUE,5,0) -> 0
A15: T1_KS1 | B15: Che livello di conoscenza hai su come creare un account e impostare le preferenze iniziali nell'app? | C15: FALSE | D15: FALSE | E15: FALSE | F15: TRUE | G15: FALSE | H15: =IF(C15=TRUE,1,0) + IF(D15=TRUE,2,0) + IF(E15=TRUE,3,0) + IF(F15=TRUE,4,0) + IF(G15=TRUE,5,0) -> 4
A16: T1_KS2 | B16: Come valuti la tua competenza nel creare l'account e impostare le preferenze iniziali come desideri? | C16: FALSE | D16: FALSE | E16: TRUE | F16: FALSE | G16: FALSE | H16: =IF(C16=TRUE,1,0) + IF(D16=TRUE,2,0) + IF(E16=TRUE,3,0) + IF(F16=TRUE,4,0) + IF(G16=TRUE,5,0) -> 3
A17: T2_KS1 | B17: Che livello di conoscenza hai su come loggare velocemente il tuo stato d'animo usando gli strumenti dell'app (scala, emoji, tag)? | C17: FALSE | D17: FALSE | E17: FALSE | F17: FALSE | G17: TRUE | H17: =IF(C17=TRUE,1,0) + IF(D17=TRUE,2,0) + IF(E17=TRUE,3,0) + IF(F17=TRUE,4,0) + IF(G17=TRUE,5,0) -> 5
A18: T2_KS2 | B18: Come valuti la tua competenza nel loggare il tuo umore in modo rapido ed efficace? | C18: FALSE | D18: FALSE | E18: FALSE | F18: FALSE | G18: TRUE | H18: =IF(C18=TRUE,1,0) + IF(D18=TRUE,2,0) + IF(E18=TRUE,3,0) + IF(F18=TRUE,4,0) + IF(G18=TRUE,5,0) -> 5
A19: T3_KS1 | B19: Che livello di conoscenza hai su come funziona la funzione di scrittura guidata (rispondere a prompt/domande)? | C19: FALSE | D19: FALSE | E19: FALSE | F19: TRUE | G19: FALSE | H19: =IF(C19=TRUE,1,0) + IF(D19=TRUE,2,0) + IF(E19=TRUE,3,0) + IF(F19=TRUE,4,0) + IF(G19=TRUE,5,0) -> 4
A20: T3_KS2 | B20: Come valuti la tua competenza nel rispondere ai prompt proposti dall'app per riflettere? | C20: FALSE | D20: FALSE | E20: FALSE | F20: FALSE | G20: TRUE | H20: =IF(C20=TRUE,1,0) + IF(D20=TRUE,2,0) + IF(E20=TRUE,3,0) + IF(F20=TRUE,4,0) + IF(G20=TRUE,5,0) -> 5
A21: T4_KS1 | B21: Che livello di conoscenza hai su come usare la funzione diario per la scrittura libera? | C21: FALSE | D21: FALSE | E21: FALSE | F21: TRUE | G21: FALSE | H21: =IF(C21=TRUE,1,0) + IF(D21=TRUE,2,0) + IF(E21=TRUE,3,0) + IF(F21=TRUE,4,0) + IF(G21=TRUE,5,0) -> 4
A22: T4_KS2 | B22: Come valuti la tua competenza nello scrivere liberamente i tuoi pensieri, emozioni o eventi nel diario dell'app? | C22: FALSE | D22: FALSE | E22: FALSE | F22: TRUE | G22: FALSE | H22: =IF(C22=TRUE,1,0) + IF(D22=TRUE,2,0) + IF(E22=TRUE,3,0) + IF(F22=TRUE,4,0) + IF(G22=TRUE,5,0) -> 4
A23: T5_KS1 | B23: Che livello di conoscenza hai su come trovare e consultare le tue registrazioni passate (umore e note del diario)? | C23: FALSE | D23: FALSE | E23: FALSE | F23: TRUE | G23: FALSE | H23: =IF(C23=TRUE,1,0) + IF(D23=TRUE,2,0) + IF(E23=TRUE,3,0) + IF(F23=TRUE,4,0) + IF(G23=TRUE,5,0) -> 4
A24: T5_KS2 | B24: Come valuti la tua competenza nel navigare tra le tue registrazioni passate per ricordare o riflettere? | C24: FALSE | D24: FALSE | E24: FALSE | F24: FALSE | G24: TRUE | H24: =IF(C24=TRUE,1,0) + IF(D24=TRUE,2,0) + IF(E24=TRUE,3,0) + IF(F24=TRUE,4,0) + IF(G24=TRUE,5,0) -> 5
A25: T6_KS1 | B25: Che livello di conoscenza hai su come accedere e interpretare i grafici, calendari o sintesi sull'andamento dell'umore/temi? | C25: FALSE | D25: FALSE | E25: FALSE | F25: FALSE | G25: TRUE | H25: =IF(C25=TRUE,1,0) + IF(D25=TRUE,2,0) + IF(E25=TRUE,3,0) + IF(F25=TRUE,4,0) + IF(G25=TRUE,5,0) -> 5
A26: T6_KS2 | B26: Come valuti la tua competenza nell'utilizzare le visualizzazioni (grafici, ecc.) per capire i tuoi pattern o progressi? | C26: FALSE | D26: FALSE | E26: FALSE | F26: FALSE | G26: TRUE | H26: =IF(C26=TRUE,1,0) + IF(D26=TRUE,2,0) + IF(E26=TRUE,3,0) + IF(F26=TRUE,4,0) + IF(G26=TRUE,5,0) -> 5
... A28: T7_KS2 | B28: Come valuti la tua competenza nell'utilizzare efficacemente gli esercizi brevi per il tuo benessere? | C28: FALSE | D28: FALSE | E28: FALSE | F28: FALSE | G28: TRUE | H28: =IF(C28=TRUE,1,0) + IF(D28=TRUE,2,0) + IF(E28=TRUE,3,0) + IF(F28=TRUE,4,0) + IF(G28=TRUE,5,0) -> 5
B29: Personal Control | C29: FALSE | D29: FALSE | E29: FALSE | F29: FALSE | G29: FALSE | H29: =IF(C29=TRUE,1,0) + IF(D29=TRUE,2,0) + IF(E29=TRUE,3,0) + IF(F29=TRUE,4,0) + IF(G29=TRUE,5,0) -> 0
A30: T3_PC1 | B30: Come giudichi la tua abilità nel gestire eventuali difficoltà o blocchi mentre rispondi ai prompt di scrittura guidata? | C30: FALSE | D30: FALSE | E30: FALSE | F30: FALSE | G30: TRUE | H30: =IF(C30=TRUE,1,0) + IF(D30=TRUE,2,0) + IF(E30=TRUE,3,0) + IF(F30=TRUE,4,0) + IF(G30=TRUE,5,0) -> 5
A31: T3_PC2 | B31: Pensi di avere il controllo su come e quanto approfonditamente rispondere ai prompt di scrittura guidata? | C31: FALSE | D31: FALSE | E31: FALSE | F31: FALSE | G31: TRUE | H31: =IF(C31=TRUE,1,0) + IF(D31=TRUE,2,0) + IF(E31=TRUE,3,0) + IF(F31=TRUE,4,0) + IF(G31=TRUE,5,0) -> 5
A32: T4_PC1 | B32: Come giudichi la tua abilità nel superare un blocco dello scrittore o un'incertezza mentre usi la funzione di scrittura libera? | C32: FALSE | D32: FALSE | E32: FALSE | F32: FALSE | G32: TRUE | H32: =IF(C32=TRUE,1,0) + IF(D32=TRUE,2,0) + IF(E32=TRUE,3,0) + IF(F32=TRUE,4,0) + IF(G32=TRUE,5,0) -> 5
A33: T4_PC2 | B33: Pensi di avere il controllo su cosa, come e quando scrivere nel tuo diario libero? | C33: FALSE | D33: FALSE | E33: FALSE | F33: FALSE | G33: TRUE | H33: =IF(C33=TRUE,1,0) + IF(D33=TRUE,2,0) + IF(E33=TRUE,3,0) + IF(F33=TRUE,4,0) + IF(G33=TRUE,5,0) -> 5
A34: T7_PC1 | B34: Come giudichi la tua abilità nel gestire eventuali distrazioni o difficoltà durante l'esecuzione di un esercizio breve guidato? | C34: FALSE | D34: FALSE | E34: FALSE | F34: TRUE | G34: FALSE | H34: =IF(C34=TRUE,1,0) + IF(D34=TRUE,2,0) + IF(E34=TRUE,3,0) + IF(F34=TRUE,4,0) + IF(G34=TRUE,5,0) -> 4
A35: T7_PC2 | B35: Pensi di avere il controllo su quando e quale esercizio breve scegliere e avviare? | C35: FALSE | D35: FALSE | E35: FALSE | F35: FALSE | G35: TRUE | H35: =IF(C35=TRUE,1,0) + IF(D35=TRUE,2,0) + IF(E35=TRUE,3,0) + IF(F35=TRUE,4,0) + IF(G35=TRUE,5,0) -> 5
B36: Motivation | C36: FALSE | D36: FALSE | E36: FALSE | F36: FALSE | G36: FALSE | H36: =IF(C36=TRUE,1,0) + IF(D36=TRUE,2,0) + IF(E36=TRUE,3,0) + IF(F36=TRUE,4,0) + IF(G36=TRUE,5,0) -> 0
A37: T1_MOT1 | B37: Quanto è facile per te compiere i passi necessari per creare l'account e impostare le preferenze? | C37: FALSE | D37: FALSE | E37: FALSE | F37: FALSE | G37: TRUE | H37: =IF(C37=TRUE,1,0) + IF(D37=TRUE,2,0) + IF(E37=TRUE,3,0) + IF(F37=TRUE,4,0) + IF(G37=TRUE,5,0) -> 5
A38: T1_MOT2 | B38: Quanto è facile per te correggere eventuali errori durante la creazione dell'account o l'impostazione delle preferenze? | C38: FALSE | D38: FALSE | E38: FALSE | F38: FALSE | G38: TRUE | H38: =IF(C38=TRUE,1,0) + IF(D38=TRUE,2,0) + IF(E38=TRUE,3,0) + IF(F38=TRUE,4,0) + IF(G38=TRUE,5,0) -> 5
A39: T2_MOT1 | B39: Quanto è facile per te compiere le azioni per loggare velocemente il tuo umore? | C39: FALSE | D39: FALSE | E39: FALSE | F39: FALSE | G39: TRUE | H39: =IF(C39=TRUE,1,0) + IF(D39=TRUE,2,0) + IF(E39=TRUE,3,0) + IF(F39=TRUE,4,0) + IF(G39=TRUE,5,0) -> 5
A40: T2_MOT2 | B40: Quanto è facile per te correggere un errore se sbagli a loggare l'umore? | C40: FALSE | D40: FALSE | E40: TRUE | F40: FALSE | G40: FALSE | H40: =IF(C40=TRUE,1,0) + IF(D40=TRUE,2,0) + IF(E40=TRUE,3,0) + IF(F40=TRUE,4,0) + IF(G40=TRUE,5,0) -> 3
A41: T3_MOT1 | B41: Quanto è facile per te iniziare e completare una sessione di scrittura guidata quando proposto dall'app? | C41: FALSE | D41: FALSE | E41: FALSE | F41: TRUE | G41: FALSE | H41: =IF(C41=TRUE,1,0) + IF(D41=TRUE,2,0) + IF(E41=TRUE,3,0) + IF(F41=TRUE,4,0) + IF(G41=TRUE,5,0) -> 4
...

Sheet Quest.Utente3
B1: Self Efficacy | C1: Scarso | D1: Sufficiente | E1: Buono | F1: Molto Buono | G1: Eccellente | H1: Valore
A2: T2_SE1 | B2: Come valuti il tuo livello di disinvoltura nel loggare velocemente il tuo stato d'animo? | C2: FALSE | D2: FALSE | E2: FALSE | F2: FALSE | G2: TRUE | H2: =IF(C2=TRUE,1,0) + IF(D2=TRUE,2,0) + IF(E2=TRUE,3,0) + IF(F2=TRUE,4,0) + IF(G2=TRUE,5,0) -> 5
A3: T2_SE2 | B3: Come valuti la tua abilità nell'usare gli strumenti forniti (scala, emoji, tag) per loggare l'umore come intendi tu? | C3: FALSE | D3: FALSE | E3: FALSE | F3: TRUE | G3: FALSE | H3: =IF(C3=TRUE,1,0) + IF(D3=TRUE,2,0) + IF(E3=TRUE,3,0) + IF(F3=TRUE,4,0) + IF(G3=TRUE,5,0) -> 4
A4: T3_SE1 | B4: Come valuti il tuo livello di disinvoltura nell'usare la funzione di scrittura guidata per riflettere? | C4: FALSE | D4: FALSE | E4: FALSE | F4: TRUE | G4: FALSE | H4: =IF(C4=TRUE,1,0) + IF(D4=TRUE,2,0) + IF(E4=TRUE,3,0) + IF(F4=TRUE,4,0) + IF(G4=TRUE,5,0) -> 4
A5: T3_SE2 | B5: Come valuti la tua abilità nell'esprimere i tuoi pensieri e sentimenti rispondendo ai prompt proposti? | C5: FALSE | D5: FALSE | E5: FALSE | F5: TRUE | G5: FALSE | H5: =IF(C5=TRUE,1,0) + IF(D5=TRUE,2,0) + IF(E5=TRUE,3,0) + IF(F5=TRUE,4,0) + IF(G5=TRUE,5,0) -> 4
A6: T4_SE1 | B6: Come valuti il tuo livello di disinvoltura nello scrivere liberamente nel diario dell'app? | C6: FALSE | D6: FALSE | E6: FALSE | F6: TRUE | G6: FALSE | H6: =IF(C6=TRUE,1,0) + IF(D6=TRUE,2,0) + IF(E6=TRUE,3,0) + IF(F6=TRUE,4,0) + IF(G6=TRUE,5,0) -> 4
A7: T4_SE2 | B7: Come valuti la tua abilità nell'esprimere liberamente ciò che senti o pensi usando la funzione diario? | C7: FALSE | D7: FALSE | E7: FALSE | F7: FALSE | G7: TRUE | H7: =IF(C7=TRUE,1,0) + IF(D7=TRUE,2,0) + IF(E7=TRUE,3,0) + IF(F7=TRUE,4,0) + IF(G7=TRUE,5,0) -> 5
A8: T5_SE1 | B8: Come valuti il tuo livello di disinvoltura nel consultare le tue registrazioni passate (umore e note)? | C8: FALSE | D8: FALSE | E8: FALSE | F8: TRUE | G8: FALSE | H8: =IF(C8=TRUE,1,0) + IF(D8=TRUE,2,0) + IF(E8=TRUE,3,0) + IF(F8=TRUE,4,0) + IF(G8=TRUE,5,0) -> 4
A9: T5_SE2 | B9: Come valuti la tua abilità nel trovare specifiche informazioni o note all'interno delle tue registrazioni passate? | C9: FALSE | D9: FALSE | E9: FALSE | F9: FALSE | G9: TRUE | H9: =IF(C9=TRUE,1,0) + IF(D9=TRUE,2,0) + IF(E9=TRUE,3,0) + IF(F9=TRUE,4,0) + IF(G9=TRUE,5,0) -> 5
A10: T6_SE1 | B10: Come valuti il tuo livello di disinvoltura nell'accedere e guardare i grafici e le sintesi dei tuoi dati? | C10: FALSE | D10: FALSE | E10: TRUE | F10: FALSE | G10: FALSE | H10: =IF(C10=TRUE,1,0) + IF(D10=TRUE,2,0) + IF(E10=TRUE,3,0) + IF(F10=TRUE,4,0) + IF(G10=TRUE,5,0) -> 3
A11: T6_SE2 | B11: Come valuti la tua abilità nell'interpretare correttamente le informazioni presentate nei grafici e nelle sintesi? | C11: FALSE | D11: FALSE | E11: FALSE | F11: FALSE | G11: TRUE | H11: =IF(C11=TRUE,1,0) + IF(D11=TRUE,2,0) + IF(E11=TRUE,3,0) + IF(F11=TRUE,4,0) + IF(G11=TRUE,5,0) -> 5
A12: T7_SE1 | B12: Come valuti il tuo livello di disinvoltura nell'utilizzare le brevi pratiche guidate (es. respirazione, mindfulness)? | C12: FALSE | D12: FALSE | E12: FALSE | F12: FALSE | G12: TRUE | H12: =IF(C12=TRUE,1,0) + IF(D12=TRUE,2,0) + IF(E12=TRUE,3,0) + IF(F12=TRUE,4,0) + IF(G12=TRUE,5,0) -> 5
A13: T7_SE2 | B13: Come valuti la tua abilità nel seguire le istruzioni e completare efficacemente gli esercizi brevi proposti? | C13: FALSE | D13: FALSE | E13: TRUE | F13: FALSE | G13: FALSE | H13: =IF(C13=TRUE,1,0) + IF(D13=TRUE,2,0) + IF(E13=TRUE,3,0) + IF(F13=TRUE,4,0) + IF(G13=TRUE,5,0) -> 3
B14: Knowledge&Skills | C14: FALSE | D14: FALSE | E14: FALSE | F14: FALSE | G14: FALSE | H14: =IF(C14=TRUE,1,0) + IF(D14=TRUE,2,0) + IF(E14=TRUE,3,0) + IF(F14=TRUE,4,0) + IF(G14=TRUE,5,0) -> 0
A15: T1_KS1 | B15: Che livello di conoscenza hai su come creare un account e impostare le preferenze iniziali nell'app? | C15: FALSE | D15: FALSE | E15: TRUE | F15: FALSE | G15: FALSE | H15: =IF(C15=TRUE,1,0) + IF(D15=TRUE,2,0) + IF(E15=TRUE,3,0) + IF(F15=TRUE,4,0) + IF(G15=TRUE,5,0) -> 3
A16: T1_KS2 | B16: Come valuti la tua competenza nel creare l'account e impostare le preferenze iniziali come desideri? | C16: FALSE | D16: FALSE | E16: FALSE | F16: FALSE | G16: TRUE | H16: =IF(C16=TRUE,1,0) + IF(D16=TRUE,2,0) + IF(E16=TRUE,3,0) + IF(F16=TRUE,4,0) + IF(G16=TRUE,5,0) -> 5
A17: T2_KS1 | B17: Che livello di conoscenza hai su come loggare velocemente il tuo stato d'animo usando gli strumenti dell'app (scala, emoji, tag)? | C17: FALSE | D17: FALSE | E17: FALSE | F17: FALSE | G17: TRUE | H17: =IF(C17=TRUE,1,0) + IF(D17=TRUE,2,0) + IF(E17=TRUE,3,0) + IF(F17=TRUE,4,0) + IF(G17=TRUE,5,0) -> 5
A18: T2_KS2 | B18: Come valuti la tua competenza nel loggare il tuo umore in modo rapido ed efficace? | C18: FALSE | D18: FALSE | E18: FALSE | F18: FALSE | G18: FALSE | H18: =IF(C18=TRUE,1,0) + IF(D18=TRUE,2,0) + IF(E18=TRUE,3,0) + IF(F18=TRUE,4,0) + IF(G18=TRUE,5,0) -> 0
A19: T3_KS1 | B19: Che livello di conoscenza hai su come funziona la funzione di scrittura guidata (rispondere a prompt/domande)? | C19: FALSE | D19: FALSE | E19: FALSE | F19: TRUE | G19: TRUE | H19: =IF(C19=TRUE,1,0) + IF(D19=TRUE,2,0) + IF(E19=TRUE,3,0) + IF(F19=TRUE,4,0) + IF(G19=TRUE,5,0) -> 9
A20: T3_KS2 | B20: Come valuti la tua competenza nel rispondere ai prompt proposti dall'app per riflettere? | C20: FALSE | D20: FALSE | E20: FALSE | F20: FALSE | G20: TRUE | H20: =IF(C20=TRUE,1,0) + IF(D20=TRUE,2,0) + IF(E20=TRUE,3,0) + IF(F20=TRUE,4,0) + IF(G20=TRUE,5,0) -> 5
A21: T4_KS1 | B21: Che livello di conoscenza hai su come usare la funzione diario per la scrittura libera? | C21: FALSE | D21: FALSE | E21: FALSE | F21: TRUE | G21: FALSE | H21: =IF(C21=TRUE,1,0) + IF(D21=TRUE,2,0) + IF(E21=TRUE,3,0) + IF(F21=TRUE,4,0) + IF(G21=TRUE,5,0) -> 4
A22: T4_KS2 | B22: Come valuti la tua competenza nello scrivere liberamente i tuoi pensieri, emozioni o eventi nel diario dell'app? | C22: FALSE | D22: FALSE | E22: FALSE | F22: FALSE | G22: TRUE | H22: =IF(C22=TRUE,1,0) + IF(D22=TRUE,2,0) + IF(E22=TRUE,3,0) + IF(F22=TRUE,4,0) + IF(G22=TRUE,5,0) -> 5
A23: T5_KS1 | B23: Che livello di conoscenza hai su come trovare e consultare le tue registrazioni passate (umore e note del diario)? | C23: FALSE | D23: FALSE | E23: FALSE | F23: FALSE | G23: TRUE | H23: =IF(C23=TRUE,1,0) + IF(D23=TRUE,2,0) + IF(E23=TRUE,3,0) + IF(F23=TRUE,4,0) + IF(G23=TRUE,5,0) -> 5
A24: T5_KS2 | B24: Come valuti la tua competenza nel navigare tra le tue registrazioni passate per ricordare o riflettere? | C24: FALSE | D24: FALSE | E24: FALSE | F24: FALSE | G24: TRUE | H24: =IF(C24=TRUE,1,0) + IF(D24=TRUE,2,0) + IF(E24=TRUE,3,0) + IF(F24=TRUE,4,0) + IF(G24=TRUE,5,0) -> 5
A25: T6_KS1 | B25: Che livello di conoscenza hai su come accedere e interpretare i grafici, calendari o sintesi sull'andamento dell'umore/temi? | C25: FALSE | D25: FALSE | E25: FALSE | F25: TRUE | G25: FALSE | H25: =IF(C25=TRUE,1,0) + IF(D25=TRUE,2,0) + IF(E25=TRUE,3,0) + IF(F25=TRUE,4,0) + IF(G25=TRUE,5,0) -> 4
A26: T6_KS2 | B26: Come valuti la tua competenza nell'utilizzare le visualizzazioni (grafici, ecc.) per capire i tuoi pattern o progressi? | C26: FALSE | D26: FALSE | E26: FALSE | F26: FALSE | G26: TRUE | H26: =IF(C26=TRUE,1,0) + IF(D26=TRUE,2,0) + IF(E26=TRUE,3,0) + IF(F26=TRUE,4,0) + IF(G26=TRUE,5,0) -> 5
... A28: T7_KS2 | B28: Come valuti la tua competenza nell'utilizzare efficacemente gli esercizi brevi per il tuo benessere? | C28: FALSE | D28: FALSE | E28: FALSE | F28: TRUE | G28: FALSE | H28: =IF(C28=TRUE,1,0) + IF(D28=TRUE,2,0) + IF(E28=TRUE,3,0) + IF(F28=TRUE,4,0) + IF(G28=TRUE,5,0) -> 4
B29: Personal Control | C29: FALSE | D29: FALSE | E29: FALSE | F29: FALSE | G29: FALSE | H29: =IF(C29=TRUE,1,0) + IF(D29=TRUE,2,0) + IF(E29=TRUE,3,0) + IF(F29=TRUE,4,0) + IF(G29=TRUE,5,0) -> 0
A30: T3_PC1 | B30: Come giudichi la tua abilità nel gestire eventuali difficoltà o blocchi mentre rispondi ai prompt di scrittura guidata? | C30: FALSE | D30: FALSE | E30: TRUE | F30: FALSE | G30: FALSE | H30: =IF(C30=TRUE,1,0) + IF(D30=TRUE,2,0) + IF(E30=TRUE,3,0) + IF(F30=TRUE,4,0) + IF(G30=TRUE,5,0) -> 3
A31: T3_PC2 | B31: Pensi di avere il controllo su come e quanto approfonditamente rispondere ai prompt di scrittura guidata? | C31: FALSE | D31: FALSE | E31: FALSE | F31: FALSE | G31: TRUE | H31: =IF(C31=TRUE,1,0) + IF(D31=TRUE,2,0) + IF(E31=TRUE,3,0) + IF(F31=TRUE,4,0) + IF(G31=TRUE,5,0) -> 5
A32: T4_PC1 | B32: Come giudichi la tua abilità nel superare un blocco dello scrittore o un'incertezza mentre usi la funzione di scrittura libera? | C32: FALSE | D32: FALSE | E32: TRUE | F32: FALSE | G32: FALSE | H32: =IF(C32=TRUE,1,0) + IF(D32=TRUE,2,0) + IF(E32=TRUE,3,0) + IF(F32=TRUE,4,0) + IF(G32=TRUE,5,0) -> 3
A33: T4_PC2 | B33: Pensi di avere il controllo su cosa, come e quando scrivere nel tuo diario libero? | C33: FALSE | D33: FALSE | E33: FALSE | F33: TRUE | G33: FALSE | H33: =IF(C33=TRUE,1,0) + IF(D33=TRUE,2,0) + IF(E33=TRUE,3,0) + IF(F33=TRUE,4,0) + IF(G33=TRUE,5,0) -> 4
A34: T7_PC1 | B34: Come giudichi la tua abilità nel gestire eventuali distrazioni o difficoltà durante l'esecuzione di un esercizio breve guidato? | C34: FALSE | D34: FALSE | E34: FALSE | F34: FALSE | G34: TRUE | H34: =IF(C34=TRUE,1,0) + IF(D34=TRUE,2,0) + IF(E34=TRUE,3,0) + IF(F34=TRUE,4,0) + IF(G34=TRUE,5,0) -> 5
A35: T7_PC2 | B35: Pensi di avere il controllo su quando e quale esercizio breve scegliere e avviare? | C35: FALSE | D35: FALSE | E35: FALSE | F35: FALSE | G35: TRUE | H35: =IF(C35=TRUE,1,0) + IF(D35=TRUE,2,0) + IF(E35=TRUE,3,0) + IF(F35=TRUE,4,0) + IF(G35=TRUE,5,0) -> 5
B36: Motivation | C36: FALSE | D36: FALSE | E36: FALSE | F36: FALSE | G36: FALSE | H36: =IF(C36=TRUE,1,0) + IF(D36=TRUE,2,0) + IF(E36=TRUE,3,0) + IF(F36=TRUE,4,0) + IF(G36=TRUE,5,0) -> 0
A37: T1_MOT1 | B37: Quanto è facile per te compiere i passi necessari per creare l'account e impostare le preferenze? | C37: FALSE | D37: FALSE | E37: FALSE | F37: FALSE | G37: TRUE | H37: =IF(C37=TRUE,1,0) + IF(D37=TRUE,2,0) + IF(E37=TRUE,3,0) + IF(F37=TRUE,4,0) + IF(G37=TRUE,5,0) -> 5
A38: T1_MOT2 | B38: Quanto è facile per te correggere eventuali errori durante la creazione dell'account o l'impostazione delle preferenze? | C38: FALSE | D38: FALSE | E38: TRUE | F38: FALSE | G38: FALSE | H38: =IF(C38=TRUE,1,0) + IF(D38=TRUE,2,0) + IF(E38=TRUE,3,0) + IF(F38=TRUE,4,0) + IF(G38=TRUE,5,0) -> 3
A39: T2_MOT1 | B39: Quanto è facile per te compiere le azioni per loggare velocemente il tuo umore? | C39: FALSE | D39: FALSE | E39: TRUE | F39: FALSE | G39: FALSE | H39: =IF(C39=TRUE,1,0) + IF(D39=TRUE,2,0) + IF(E39=TRUE,3,0) + IF(F39=TRUE,4,0) + IF(G39=TRUE,5,0) -> 3
A40: T2_MOT2 | B40: Quanto è facile per te correggere un errore se sbagli a loggare l'umore? | C40: FALSE | D40: FALSE | E40: FALSE | F40: FALSE | G40: TRUE | H40: =IF(C40=TRUE,1,0) + IF(D40=TRUE,2,0) + IF(E40=TRUE,3,0) + IF(F40=TRUE,4,0) + IF(G40=TRUE,5,0) -> 5
A41: T3_MOT1 | B41: Quanto è facile per te iniziare e completare una sessione di scrittura guidata quando proposto dall'app? | C41: FALSE | D41: FALSE | E41: FALSE | F41: FALSE | G41: TRUE | H41: =IF(C41=TRUE,1,0) + IF(D41=TRUE,2,0) + IF(E41=TRUE,3,0) + IF(F41=TRUE,4,0) + IF(G41=TRUE,5,0) -> 5
...

Sheet Quest.Utente4
B1: Self Efficacy | C1: Scarso | D1: Sufficiente | E1: Buono | F1: Molto Buono | G1: Eccellente | H1: Valore
A2: T2_SE1 | B2: Come valuti il tuo livello di disinvoltura nel loggare velocemente il tuo stato d'animo? | C2: FALSE | D2: FALSE | E2: FALSE | F2: FALSE | G2: TRUE | H2: =IF(C2=TRUE,1,0) + IF(D2=TRUE,2,0) + IF(E2=TRUE,3,0) + IF(F2=TRUE,4,0) + IF(G2=TRUE,5,0) -> 5
A3: T2_SE2 | B3: Come valuti la tua abilità nell'usare gli strumenti forniti (scala, emoji, tag) per loggare l'umore come intendi tu? | C3: FALSE | D3: FALSE | E3: FALSE | F3: TRUE | G3: FALSE | H3: =IF(C3=TRUE,1,0) + IF(D3=TRUE,2,0) + IF(E3=TRUE,3,0) + IF(F3=TRUE,4,0) + IF(G3=TRUE,5,0) -> 4
A4: T3_SE1 | B4: Come valuti il tuo livello di disinvoltura nell'usare la funzione di scrittura guidata per riflettere? | C4: FALSE | D4: FALSE | E4: FALSE | F4: FALSE | G4: TRUE | H4: =IF(C4=TRUE,1,0) + IF(D4=TRUE,2,0) + IF(E4=TRUE,3,0) + IF(F4=TRUE,4,0) + IF(G4=TRUE,5,0) -> 5
A5: T3_SE2 | B5: Come valuti la tua abilità nell'esprimere i tuoi pensieri e sentimenti rispondendo ai prompt proposti? | C5: FALSE | D5: FALSE | E5: FALSE | F5: FALSE | G5: TRUE | H5: =IF(C5=TRUE,1,0) + IF(D5=TRUE,2,0) + IF(E5=TRUE,3,0) + IF(F5=TRUE,4,0) + IF(G5=TRUE,5,0) -> 5
A6: T4_SE1 | B6: Come valuti il tuo livello di disinvoltura nello scrivere liberamente nel diario dell'app? | C6: FALSE | D6: FALSE | E6: FALSE | F6: FALSE | G6: FALSE | H6: =IF(C6=TRUE,1,0) + IF(D6=TRUE,2,0) + IF(E6=TRUE,3,0) + IF(F6=TRUE,4,0) + IF(G6=TRUE,5,0) -> 0
A7: T4_SE2 | B7: Come valuti la tua abilità nell'esprimere liberamente ciò che senti o pensi usando la funzione diario? | C7: FALSE | D7: FALSE | E7: FALSE | F7: TRUE | G7: FALSE | H7: =IF(C7=TRUE,1,0) + IF(D7=TRUE,2,0) + IF(E7=TRUE,3,0) + IF(F7=TRUE,4,0) + IF(G7=TRUE,5,0) -> 4
A8: T5_SE1 | B8: Come valuti il tuo livello di disinvoltura nel consultare le tue registrazioni passate (umore e note)? | C8: FALSE | D8: FALSE | E8: FALSE | F8: TRUE | G8: FALSE | H8: =IF(C8=TRUE,1,0) + IF(D8=TRUE,2,0) + IF(E8=TRUE,3,0) + IF(F8=TRUE,4,0) + IF(G8=TRUE,5,0) -> 4
A9: T5_SE2 | B9: Come valuti la tua abilità nel trovare specifiche informazioni o note all'interno delle tue registrazioni passate? | C9: FALSE | D9: FALSE | E9: FALSE | F9: FALSE | G9: TRUE | H9: =IF(C9=TRUE,1,0) + IF(D9=TRUE,2,0) + IF(E9=TRUE,3,0) + IF(F9=TRUE,4,0) + IF(G9=TRUE,5,0) -> 5
A10: T6_SE1 | B10: Come valuti il tuo livello di disinvoltura nell'accedere e guardare i grafici e le sintesi dei tuoi dati? | C10: FALSE | D10: FALSE | E10: FALSE | F10: TRUE | G10: FALSE | H10: =IF(C10=TRUE,1,0) + IF(D10=TRUE,2,0) + IF(E10=TRUE,3,0) + IF(F10=TRUE,4,0) + IF(G10=TRUE,5,0) -> 4
A11: T6_SE2 | B11: Come valuti la tua abilità nell'interpretare correttamente le informazioni presentate nei grafici e nelle sintesi? | C11: FALSE | D11: FALSE | E11: FALSE | F11: TRUE | G11: FALSE | H11: =IF(C11=TRUE,1,0) + IF(D11=TRUE,2,0) + IF(E11=TRUE,3,0) + IF(F11=TRUE,4,0) + IF(G11=TRUE,5,0) -> 4
A12: T7_SE1 | B12: Come valuti il tuo livello di disinvoltura nell'utilizzare le brevi pratiche guidate (es. respirazione, mindfulness)? | C12: FALSE | D12: FALSE | E12: TRUE | F12: FALSE | G12: FALSE | H12: =IF(C12=TRUE,1,0) + IF(D12=TRUE,2,0) + IF(E12=TRUE,3,0) + IF(F12=TRUE,4,0) + IF(G12=TRUE,5,0) -> 3
A13: T7_SE2 | B13: Come valuti la tua abilità nel seguire le istruzioni e completare efficacemente gli esercizi brevi proposti? | C13: FALSE | D13: FALSE | E13: FALSE | F13: FALSE | G13: TRUE | H13: =IF(C13=TRUE,1,0) + IF(D13=TRUE,2,0) + IF(E13=TRUE,3,0) + IF(F13=TRUE,4,0) + IF(G13=TRUE,5,0) -> 5
B14: Knowledge&Skills | C14: FALSE | D14: FALSE | E14: FALSE | F14: FALSE | G14: FALSE | H14: =IF(C14=TRUE,1,0) + IF(D14=TRUE,2,0) + IF(E14=TRUE,3,0) + IF(F14=TRUE,4,0) + IF(G14=TRUE,5,0) -> 0
A15: T1_KS1 | B15: Che livello di conoscenza hai su come creare un account e impostare le preferenze iniziali nell'app? | C15: FALSE | D15: FALSE | E15: FALSE | F15: FALSE | G15: FALSE | H15: =IF(C15=TRUE,1,0) + IF(D15=TRUE,2,0) + IF(E15=TRUE,3,0) + IF(F15=TRUE,4,0) + IF(G15=TRUE,5,0) -> 0
A16: T1_KS2 | B16: Come valuti la tua competenza nel creare l'account e impostare le preferenze iniziali come desideri? | C16: FALSE | D16: FALSE | E16: FALSE | F16: TRUE | G16: FALSE | H16: =IF(C16=TRUE,1,0) + IF(D16=TRUE,2,0) + IF(E16=TRUE,3,0) + IF(F16=TRUE,4,0) + IF(G16=TRUE,5,0) -> 4
A17: T2_KS1 | B17: Che livello di conoscenza hai su come loggare velocemente il tuo stato d'animo usando gli strumenti dell'app (scala, emoji, tag)? | C17: FALSE | D17: FALSE | E17: FALSE | F17: FALSE | G17: FALSE | H17: =IF(C17=TRUE,1,0) + IF(D17=TRUE,2,0) + IF(E17=TRUE,3,0) + IF(F17=TRUE,4,0) + IF(G17=TRUE,5,0) -> 0
A18: T2_KS2 | B18: Come valuti la tua competenza nel loggare il tuo umore in modo rapido ed efficace? | C18: FALSE | D18: FALSE | E18: FALSE | F18: FALSE | G18: TRUE | H18: =IF(C18=TRUE,1,0) + IF(D18=TRUE,2,0) + IF(E18=TRUE,3,0) + IF(F18=TRUE,4,0) + IF(G18=TRUE,5,0) -> 5
A19: T3_KS1 | B19: Che livello di conoscenza hai su come funziona la funzione di scrittura guidata (rispondere a prompt/domande)? | C19: FALSE | D19: FALSE | E19: FALSE | F19: FALSE | G19: TRUE | H19: =IF(C19=TRUE,1,0) + IF(D19=TRUE,2,0) + IF(E19=TRUE,3,0) + IF(F19=TRUE,4,0) + IF(G19=TRUE,5,0) -> 5
A20: T3_KS2 | B20: Come valuti la tua competenza nel rispondere ai prompt proposti dall'app per riflettere? | C20: FALSE | D20: FALSE | E20: FALSE | F20: FALSE | G20: FALSE | H20: =IF(C20=TRUE,1,0) + IF(D20=TRUE,2,0) + IF(E20=TRUE,3,0) + IF(F20=TRUE,4,0) + IF(G20=TRUE,5,0) -> 0
A21: T4_KS1 | B21: Che livello di conoscenza hai su come usare la funzione diario per la scrittura libera? | C21: FALSE | D21: FALSE | E21: FALSE | F21: TRUE | G21: FALSE | H21: =IF(C21=TRUE,1,0) + IF(D21=TRUE,2,0) + IF(E21=TRUE,3,0) + IF(F21=TRUE,4,0) + IF(G21=TRUE,5,0) -> 4
A22: T4_KS2 | B22: Come valuti la tua competenza nello scrivere liberamente i tuoi pensieri, emozioni o eventi nel diario dell'app? | C22: FALSE | D22: FALSE | E22: FALSE | F22: FALSE | G22: FALSE | H22: =IF(C22=TRUE,1,0) + IF(D22=TRUE,2,0) + IF(E22=TRUE,3,0) + IF(F22=TRUE,4,0) + IF(G22=TRUE,5,0) -> 0
A23: T5_KS1 | B23: Che livello di conoscenza hai su come trovare e consultare le tue registrazioni passate (umore e note del diario)? | C23: FALSE | D23: FALSE | E23: FALSE | F23: FALSE | G23: FALSE | H23: =IF(C23=TRUE,1,0) + IF(D23=TRUE,2,0) + IF(E23=TRUE,3,0) + IF(F23=TRUE,4,0) + IF(G23=TRUE,5,0) -> 0
A24: T5_KS2 | B24: Come valuti la tua competenza nel navigare tra le tue registrazioni passate per ricordare o riflettere? | C24: FALSE | D24: FALSE | E24: FALSE | F24: FALSE | G24: TRUE | H24: =IF(C24=TRUE,1,0) + IF(D24=TRUE,2,0) + IF(E24=TRUE,3,0) + IF(F24=TRUE,4,0) + IF(G24=TRUE,5,0) -> 5
A25: T6_KS1 | B25: Che livello di conoscenza hai su come accedere e interpretare i grafici, calendari o sintesi sull'andamento dell'umore/temi? | C25: FALSE | D25: FALSE | E25: FALSE | F25: FALSE | G25: FALSE | H25: =IF(C25=TRUE,1,0) + IF(D25=TRUE,2,0) + IF(E25=TRUE,3,0) + IF(F25=TRUE,4,0) + IF(G25=TRUE,5,0) -> 0
A26: T6_KS2 | B26: Come valuti la tua competenza nell'utilizzare le visualizzazioni (grafici, ecc.) per capire i tuoi pattern o progressi? | C26: FALSE | D26: FALSE | E26: FALSE | F26: TRUE | G26: FALSE | H26: =IF(C26=TRUE,1,0) + IF(D26=TRUE,2,0) + IF(E26=TRUE,3,0) + IF(F26=TRUE,4,0) + IF(G26=TRUE,5,0) -> 4
... A28: T7_KS2 | B28: Come valuti la tua competenza nell'utilizzare efficacemente gli esercizi brevi per il tuo benessere? | C28: FALSE | D28: FALSE | E28: FALSE | F28: TRUE | G28: TRUE | H28: =IF(C28=TRUE,1,0) + IF(D28=TRUE,2,0) + IF(E28=TRUE,3,0) + IF(F28=TRUE,4,0) + IF(G28=TRUE,5,0) -> 9
B29: Personal Control | C29: FALSE | D29: FALSE | E29: FALSE | F29: FALSE | G29: FALSE | H29: =IF(C29=TRUE,1,0) + IF(D29=TRUE,2,0) + IF(E29=TRUE,3,0) + IF(F29=TRUE,4,0) + IF(G29=TRUE,5,0) -> 0
A30: T3_PC1 | B30: Come giudichi la tua abilità nel gestire eventuali difficoltà o blocchi mentre rispondi ai prompt di scrittura guidata? | C30: FALSE | D30: FALSE | E30: FALSE | F30: TRUE | G30: FALSE | H30: =IF(C30=TRUE,1,0) + IF(D30=TRUE,2,0) + IF(E30=TRUE,3,0) + IF(F30=TRUE,4,0) + IF(G30=TRUE,5,0) -> 4
A31: T3_PC2 | B31: Pensi di avere il controllo su come e quanto approfonditamente rispondere ai prompt di scrittura guidata? | C31: FALSE | D31: FALSE | E31: FALSE | F31: FALSE | G31: TRUE | H31: =IF(C31=TRUE,1,0) + IF(D31=TRUE,2,0) + IF(E31=TRUE,3,0) + IF(F31=TRUE,4,0) + IF(G31=TRUE,5,0) -> 5
A32: T4_PC1 | B32: Come giudichi la tua abilità nel superare un blocco dello scrittore o un'incertezza mentre usi la funzione di scrittura libera? | C32: FALSE | D32: FALSE | E32: FALSE | F32: FALSE | G32: FALSE | H32: =IF(C32=TRUE,1,0) + IF(D32=TRUE,2,0) + IF(E32=TRUE,3,0) + IF(F32=TRUE,4,0) + IF(G32=TRUE,5,0) -> 0
A33: T4_PC2 | B33: Pensi di avere il controllo su cosa, come e quando scrivere nel tuo diario libero? | C33: FALSE | D33: FALSE | E33: FALSE | F33: TRUE | G33: FALSE | H33: =IF(C33=TRUE,1,0) + IF(D33=TRUE,2,0) + IF(E33=TRUE,3,0) + IF(F33=TRUE,4,0) + IF(G33=TRUE,5,0) -> 4
A34: T7_PC1 | B34: Come giudichi la tua abilità nel gestire eventuali distrazioni o difficoltà durante l'esecuzione di un esercizio breve guidato? | C34: FALSE | D34: FALSE | E34: TRUE | F34: FALSE | G34: FALSE | H34: =IF(C34=TRUE,1,0) + IF(D34=TRUE,2,0) + IF(E34=TRUE,3,0) + IF(F34=TRUE,4,0) + IF(G34=TRUE,5,0) -> 3
A35: T7_PC2 | B35: Pensi di avere il controllo su quando e quale esercizio breve scegliere e avviare? | C35: FALSE | D35: FALSE | E35: FALSE | F35: FALSE | G35: TRUE | H35: =IF(C35=TRUE,1,0) + IF(D35=TRUE,2,0) + IF(E35=TRUE,3,0) + IF(F35=TRUE,4,0) + IF(G35=TRUE,5,0) -> 5
B36: Motivation | C36: FALSE | D36: FALSE | E36: FALSE | F36: FALSE | G36: FALSE | H36: =IF(C36=TRUE,1,0) + IF(D36=TRUE,2,0) + IF(E36=TRUE,3,0) + IF(F36=TRUE,4,0) + IF(G36=TRUE,5,0) -> 0
A37: T1_MOT1 | B37: Quanto è facile per te compiere i passi necessari per creare l'account e impostare le preferenze? | C37: FALSE | D37: FALSE | E37: FALSE | F37: TRUE | G37: FALSE | H37: =IF(C37=TRUE,1,0) + IF(D37=TRUE,2,0) + IF(E37=TRUE,3,0) + IF(F37=TRUE,4,0) + IF(G37=TRUE,5,0) -> 4
A38: T1_MOT2 | B38: Quanto è facile per te correggere eventuali errori durante la creazione dell'account o l'impostazione delle preferenze? | C38: FALSE | D38: FALSE | E38: TRUE | F38: FALSE | G38: FALSE | H38: =IF(C38=TRUE,1,0) + IF(D38=TRUE,2,0) + IF(E38=TRUE,3,0) + IF(F38=TRUE,4,0) + IF(G38=TRUE,5,0) -> 3
A39: T2_MOT1 | B39: Quanto è facile per te compiere le azioni per loggare velocemente il tuo umore? | C39: FALSE | D39: FALSE | E39: FALSE | F39: TRUE | G39: FALSE | H39: =IF(C39=TRUE,1,0) + IF(D39=TRUE,2,0) + IF(E39=TRUE,3,0) + IF(F39=TRUE,4,0) + IF(G39=TRUE,5,0) -> 4
A40: T2_MOT2 | B40: Quanto è facile per te correggere un errore se sbagli a loggare l'umore? | C40: FALSE | D40: FALSE | E40: FALSE | F40: FALSE | G40: TRUE | H40: =IF(C40=TRUE,1,0) + IF(D40=TRUE,2,0) + IF(E40=TRUE,3,0) + IF(F40=TRUE,4,0) + IF(G40=TRUE,5,0) -> 5
A41: T3_MOT1 | B41: Quanto è facile per te iniziare e completare una sessione di scrittura guidata quando proposto dall'app? | C41: FALSE | D41: FALSE | E41: FALSE | F41: TRUE | G41: FALSE | H41: =IF(C41=TRUE,1,0) + IF(D41=TRUE,2,0) + IF(E41=TRUE,3,0) + IF(F41=TRUE,4,0) + IF(G41=TRUE,5,0) -> 4
...

Sheet Quest.Utente5
B1: Self Efficacy | C1: Scarso | D1: Sufficiente | E1: Buono | F1: Molto Buono | G1: Eccellente | H1: Valore
A2: T2_SE1 | B2: Come valuti il tuo livello di disinvoltura nel loggare velocemente il tuo stato d'animo? | C2: FALSE | D2: FALSE | E2: FALSE | F2: FALSE | G2: TRUE | H2: =IF(C2=TRUE,1,0) + IF(D2=TRUE,2,0) + IF(E2=TRUE,3,0) + IF(F2=TRUE,4,0) + IF(G2=TRUE,5,0) -> 5
A3: T2_SE2 | B3: Come valuti la tua abilità nell'usare gli strumenti forniti (scala, emoji, tag) per loggare l'umore come intendi tu? | C3: FALSE | D3: FALSE | E3: FALSE | F3: FALSE | G3: TRUE | H3: =IF(C3="X",1)+IF(D3="X",2)+IF(E3="X",3)+IF(F3="X",4)+IF(G3="X",5) -> 0
A4: T3_SE1 | B4: Come valuti il tuo livello di disinvoltura nell'usare la funzione di scrittura guidata per riflettere? | C4: FALSE | D4: FALSE | E4: FALSE | F4: FALSE | G4: TRUE | H4: =IF(C4="X",1)+IF(D4="X",2)+IF(E4="X",3)+IF(F4="X",4)+IF(G4="X",5) -> 0
A5: T3_SE2 | B5: Come valuti la tua abilità nell'esprimere i tuoi pensieri e sentimenti rispondendo ai prompt proposti? | C5: FALSE | D5: FALSE | E5: FALSE | F5: FALSE | G5: TRUE | H5: =IF(C5="X",1)+IF(D5="X",2)+IF(E5="X",3)+IF(F5="X",4)+IF(G5="X",5) -> 0
A6: T4_SE1 | B6: Come valuti il tuo livello di disinvoltura nello scrivere liberamente nel diario dell'app? | C6: FALSE | D6: FALSE | E6: FALSE | F6: TRUE | G6: FALSE | H6: =IF(C6="X",1)+IF(D6="X",2)+IF(E6="X",3)+IF(F6="X",4)+IF(G6="X",5) -> 0
A7: T4_SE2 | B7: Come valuti la tua abilità nell'esprimere liberamente ciò che senti o pensi usando la funzione diario? | C7: FALSE | D7: FALSE | E7: FALSE | F7: FALSE | G7: TRUE | H7: =IF(C7="X",1)+IF(D7="X",2)+IF(E7="X",3)+IF(F7="X",4)+IF(G7="X",5) -> 0
A8: T5_SE1 | B8: Come valuti il tuo livello di disinvoltura nel consultare le tue registrazioni passate (umore e note)? | C8: FALSE | D8: FALSE | E8: FALSE | F8: FALSE | G8: TRUE | H8: =IF(C8="X",1)+IF(D8="X",2)+IF(E8="X",3)+IF(F8="X",4)+IF(G8="X",5) -> 0
A9: T5_SE2 | B9: Come valuti la tua abilità nel trovare specifiche informazioni o note all'interno delle tue registrazioni passate? | C9: FALSE | D9: FALSE | E9: FALSE | F9: FALSE | G9: TRUE | H9: =IF(C9="X",1)+IF(D9="X",2)+IF(E9="X",3)+IF(F9="X",4)+IF(G9="X",5) -> 0
A10: T6_SE1 | B10: Come valuti il tuo livello di disinvoltura nell'accedere e guardare i grafici e le sintesi dei tuoi dati? | C10: FALSE | D10: FALSE | E10: FALSE | F10: FALSE | G10: TRUE | H10: =IF(C10="X",1)+IF(D10="X",2)+IF(E10="X",3)+IF(F10="X",4)+IF(G10="X",5) -> 0
A11: T6_SE2 | B11: Come valuti la tua abilità nell'interpretare correttamente le informazioni presentate nei grafici e nelle sintesi? | C11: FALSE | D11: FALSE | E11: FALSE | F11: TRUE | G11: FALSE | H11: =IF(C11="X",1)+IF(D11="X",2)+IF(E11="X",3)+IF(F11="X",4)+IF(G11="X",5) -> 0
A12: T7_SE1 | B12: Come valuti il tuo livello di disinvoltura nell'utilizzare le brevi pratiche guidate (es. respirazione, mindfulness)? | C12: FALSE | D12: FALSE | E12: FALSE | F12: FALSE | G12: TRUE | H12: =IF(C12="X",1)+IF(D12="X",2)+IF(E12="X",3)+IF(F12="X",4)+IF(G12="X",5) -> 0
A13: T7_SE2 | B13: Come valuti la tua abilità nel seguire le istruzioni e completare efficacemente gli esercizi brevi proposti? | C13: FALSE | D13: FALSE | E13: FALSE | F13: FALSE | G13: TRUE | H13: =IF(C13="X",1)+IF(D13="X",2)+IF(E13="X",3)+IF(F13="X",4)+IF(G13="X",5) -> 0
B14: Knowledge&Skills | C14: FALSE | D14: FALSE | E14: FALSE | F14: FALSE | G14: FALSE | H14: =IF(C14="X",1)+IF(D14="X",2)+IF(E14="X",3)+IF(F14="X",4)+IF(G14="X",5) -> 0
A15: T1_KS1 | B15: Che livello di conoscenza hai su come creare un account e impostare le preferenze iniziali nell'app? | C15: FALSE | D15: FALSE | E15: FALSE | F15: FALSE | G15: TRUE | H15: =IF(C15="X",1)+IF(D15="X",2)+IF(E15="X",3)+IF(F15="X",4)+IF(G15="X",5) -> 0
A16: T1_KS2 | B16: Come valuti la tua competenza nel creare l'account e impostare le preferenze iniziali come desideri? | C16: FALSE | D16: FALSE | E16: FALSE | F16: FALSE | G16: TRUE | H16: =IF(C16="X",1)+IF(D16="X",2)+IF(E16="X",3)+IF(F16="X",4)+IF(G16="X",5) -> 0
A17: T2_KS1 | B17: Che livello di conoscenza hai su come loggare velocemente il tuo stato d'animo usando gli strumenti dell'app (scala, emoji, tag)? | C17: FALSE | D17: FALSE | E17: FALSE | F17: FALSE | G17: TRUE | H17: =IF(C17="X",1)+IF(D17="X",2)+IF(E17="X",3)+IF(F17="X",4)+IF(G17="X",5) -> 0
A18: T2_KS2 | B18: Come valuti la tua competenza nel loggare il tuo umore in modo rapido ed efficace? | C18: FALSE | D18: FALSE | E18: FALSE | F18: FALSE | G18: TRUE | H18: =IF(C18="X",1)+IF(D18="X",2)+IF(E18="X",3)+IF(F18="X",4)+IF(G18="X",5) -> 0
A19: T3_KS1 | B19: Che livello di conoscenza hai su come funziona la funzione di scrittura guidata (rispondere a prompt/domande)? | C19: FALSE | D19: FALSE | E19: FALSE | F19: TRUE | G19: FALSE | H19: =IF(C19="X",1)+IF(D19="X",2)+IF(E19="X",3)+IF(F19="X",4)+IF(G19="X",5) -> 0
A20: T3_KS2 | B20: Come valuti la tua competenza nel rispondere ai prompt proposti dall'app per riflettere? | C20: FALSE | D20: FALSE | E20: FALSE | F20: FALSE | G20: TRUE | H20: =IF(C20="X",1)+IF(D20="X",2)+IF(E20="X",3)+IF(F20="X",4)+IF(G20="X",5) -> 0
A21: T4_KS1 | B21: Che livello di conoscenza hai su come usare la funzione diario per la scrittura libera? | C21: FALSE | D21: FALSE | E21: FALSE | F21: FALSE | G21: TRUE | H21: =IF(C21="X",1)+IF(D21="X",2)+IF(E21="X",3)+IF(F21="X",4)+IF(G21="X",5) -> 0
A22: T4_KS2 | B22: Come valuti la tua competenza nello scrivere liberamente i tuoi pensieri, emozioni o eventi nel diario dell'app? | C22: FALSE | D22: FALSE | E22: FALSE | F22: FALSE | G22: TRUE | H22: =IF(C22="X",1)+IF(D22="X",2)+IF(E22="X",3)+IF(F22="X",4)+IF(G22="X",5) -> 0
A23: T5_KS1 | B23: Che livello di conoscenza hai su come trovare e consultare le tue registrazioni passate (umore e note del diario)? | C23: FALSE | D23: FALSE | E23: FALSE | F23: TRUE | G23: FALSE | H23: =IF(C23="X",1)+IF(D23="X",2)+IF(E23="X",3)+IF(F23="X",4)+IF(G23="X",5) -> 0
A24: T5_KS2 | B24: Come valuti la tua competenza nel navigare tra le tue registrazioni passate per ricordare o riflettere? | C24: FALSE | D24: FALSE | E24: FALSE | F24: FALSE | G24: TRUE | H24: =IF(C24="X",1)+IF(D24="X",2)+IF(E24="X",3)+IF(F24="X",4)+IF(G24="X",5) -> 0
A25: T6_KS1 | B25: Che livello di conoscenza hai su come accedere e interpretare i grafici, calendari o sintesi sull'andamento dell'umore/temi? | C25: FALSE | D25: FALSE | E25: FALSE | F25: TRUE | G25: FALSE | H25: =IF(C25="X",1)+IF(D25="X",2)+IF(E25="X",3)+IF(F25="X",4)+IF(G25="X",5) -> 0
A26: T6_KS2 | B26: Come valuti la tua competenza nell'utilizzare le visualizzazioni (grafici, ecc.) per capire i tuoi pattern o progressi? | C26: FALSE | D26: FALSE | E26: FALSE | F26: FALSE | G26: TRUE | H26: =IF(C26="X",1)+IF(D26="X",2)+IF(E26="X",3)+IF(F26="X",4)+IF(G26="X",5) -> 0
... A28: T7_KS2 | B28: Come valuti la tua competenza nell'utilizzare efficacemente gli esercizi brevi per il tuo benessere? | C28: FALSE | D28: FALSE | E28: FALSE | F28: FALSE | G28: TRUE | H28: =IF(C28="X",1)+IF(D28="X",2)+IF(E28="X",3)+IF(F28="X",4)+IF(G28="X",5) -> 0
B29: Personal Control | C29: FALSE | D29: FALSE | E29: FALSE | F29: FALSE | G29: FALSE | H29: =IF(C29="X",1)+IF(D29="X",2)+IF(E29="X",3)+IF(F29="X",4)+IF(G29="X",5) -> 0
A30: T3_PC1 | B30: Come giudichi la tua abilità nel gestire eventuali difficoltà o blocchi mentre rispondi ai prompt di scrittura guidata? | C30: FALSE | D30: FALSE | E30: FALSE | F30: FALSE | G30: TRUE | H30: =IF(C30="X",1)+IF(D30="X",2)+IF(E30="X",3)+IF(F30="X",4)+IF(G30="X",5) -> 0
A31: T3_PC2 | B31: Pensi di avere il controllo su come e quanto approfonditamente rispondere ai prompt di scrittura guidata? | C31: FALSE | D31: FALSE | E31: FALSE | F31: FALSE | G31: TRUE | H31: =IF(C31="X",1)+IF(D31="X",2)+IF(E31="X",3)+IF(F31="X",4)+IF(G31="X",5) -> 0
A32: T4_PC1 | B32: Come giudichi la tua abilità nel superare un blocco dello scrittore o un'incertezza mentre usi la funzione di scrittura libera? | C32: FALSE | D32: FALSE | E32: FALSE | F32: FALSE | G32: TRUE | H32: =IF(C32="X",1)+IF(D32="X",2)+IF(E32="X",3)+IF(F32="X",4)+IF(G32="X",5) -> 0
A33: T4_PC2 | B33: Pensi di avere il controllo su cosa, come e quando scrivere nel tuo diario libero? | C33: FALSE | D33: FALSE | E33: FALSE | F33: FALSE | G33: TRUE | H33: =IF(C33="X",1)+IF(D33="X",2)+IF(E33="X",3)+IF(F33="X",4)+IF(G33="X",5) -> 0
A34: T7_PC1 | B34: Come giudichi la tua abilità nel gestire eventuali distrazioni o difficoltà durante l'esecuzione di un esercizio breve guidato? | C34: FALSE | D34: FALSE | E34: FALSE | F34: TRUE | G34: FALSE | H34: =IF(C34="X",1)+IF(D34="X",2)+IF(E34="X",3)+IF(F34="X",4)+IF(G34="X",5) -> 0
A35: T7_PC2 | B35: Pensi di avere il controllo su quando e quale esercizio breve scegliere e avviare? | C35: FALSE | D35: FALSE | E35: FALSE | F35: FALSE | G35: TRUE | H35: =IF(C35="X",1)+IF(D35="X",2)+IF(E35="X",3)+IF(F35="X",4)+IF(G35="X",5) -> 0
B36: Motivation | C36: FALSE | D36: FALSE | E36: FALSE | F36: FALSE | G36: FALSE | H36: =IF(C36="X",1)+IF(D36="X",2)+IF(E36="X",3)+IF(F36="X",4)+IF(G36="X",5) -> 0
A37: T1_MOT1 | B37: Quanto è facile per te compiere i passi necessari per creare l'account e impostare le preferenze? | C37: FALSE | D37: FALSE | E37: FALSE | F37: FALSE | G37: TRUE | H37: =IF(C37="X",1)+IF(D37="X",2)+IF(E37="X",3)+IF(F37="X",4)+IF(G37="X",5) -> 0
A38: T1_MOT2 | B38: Quanto è facile per te correggere eventuali errori durante la creazione dell'account o l'impostazione delle preferenze? | C38: FALSE | D38: FALSE | E38: FALSE | F38: FALSE | G38: TRUE | H38: =IF(C38="X",1)+IF(D38="X",2)+IF(E38="X",3)+IF(F38="X",4)+IF(G38="X",5) -> 0
A39: T2_MOT1 | B39: Quanto è facile per te compiere le azioni per loggare velocemente il tuo umore? | C39: FALSE | D39: FALSE | E39: FALSE | F39: TRUE | G39: FALSE | H39: =IF(C39="X",1)+IF(D39="X",2)+IF(E39="X",3)+IF(F39="X",4)+IF(G39="X",5) -> 0
A40: T2_MOT2 | B40: Quanto è facile per te correggere un errore se sbagli a loggare l'umore? | C40: FALSE | D40: FALSE | E40: FALSE | F40: TRUE | G40: FALSE | H40: =IF(C40="X",1)+IF(D40="X",2)+IF(E40="X",3)+IF(F40="X",4)+IF(G40="X",5) -> 0
A41: T3_MOT1 | B41: Quanto è facile per te iniziare e completare una sessione di scrittura guidata quando proposto dall'app? | C41: FALSE | D41: FALSE | E41: FALSE | F41: TRUE | G41: FALSE | H41: =IF(C41="X",1)+IF(D41="X",2)+IF(E41="X",3)+IF(F41="X",4)+IF(G41="X",5) -> 0
...

Sheet Quest.Utente6
B1: Self Efficacy | C1: Scarso | D1: Sufficiente | E1: Buono | F1: Molto Buono | G1: Eccellente | H1: Valore
A2: T2_SE1 | B2: Come valuti il tuo livello di disinvoltura nel loggare velocemente il tuo stato d'animo? | C2: FALSE | D2: FALSE | E2: FALSE | F2: FALSE | G2: TRUE | H2: =IF(C2=TRUE,1,0) + IF(D2=TRUE,2,0) + IF(E2=TRUE,3,0) + IF(F2=TRUE,4,0) + IF(G2=TRUE,5,0) -> 5
A3: T2_SE2 | B3: Come valuti la tua abilità nell'usare gli strumenti forniti (scala, emoji, tag) per loggare l'umore come intendi tu? | C3: FALSE | D3: FALSE | E3: FALSE | F3: FALSE | G3: TRUE | H3: =IF(C3=TRUE,1,0) + IF(D3=TRUE,2,0) + IF(E3=TRUE,3,0) + IF(F3=TRUE,4,0) + IF(G3=TRUE,5,0) -> 5
A4: T3_SE1 | B4: Come valuti il tuo livello di disinvoltura nell'usare la funzione di scrittura guidata per riflettere? | C4: FALSE | D4: FALSE | E4: FALSE | F4: TRUE | G4: FALSE | H4: =IF(C4=TRUE,1,0) + IF(D4=TRUE,2,0) + IF(E4=TRUE,3,0) + IF(F4=TRUE,4,0) + IF(G4=TRUE,5,0) -> 4
A5: T3_SE2 | B5: Come valuti la tua abilità nell'esprimere i tuoi pensieri e sentimenti rispondendo ai prompt proposti? | C5: FALSE | D5: FALSE | E5: TRUE | F5: FALSE | G5: FALSE | H5: =IF(C5=TRUE,1,0) + IF(D5=TRUE,2,0) + IF(E5=TRUE,3,0) + IF(F5=TRUE,4,0) + IF(G5=TRUE,5,0) -> 3
A6: T4_SE1 | B6: Come valuti il tuo livello di disinvoltura nello scrivere liberamente nel diario dell'app? | C6: FALSE | D6: FALSE | E6: FALSE | F6: TRUE | G6: FALSE | H6: =IF(C6=TRUE,1,0) + IF(D6=TRUE,2,0) + IF(E6=TRUE,3,0) + IF(F6=TRUE,4,0) + IF(G6=TRUE,5,0) -> 4
A7: T4_SE2 | B7: Come valuti la tua abilità nell'esprimere liberamente ciò che senti o pensi usando la funzione diario? | C7: FALSE | D7: FALSE | E7: FALSE | F7: FALSE | G7: TRUE | H7: =IF(C7=TRUE,1,0) + IF(D7=TRUE,2,0) + IF(E7=TRUE,3,0) + IF(F7=TRUE,4,0) + IF(G7=TRUE,5,0) -> 5
A8: T5_SE1 | B8: Come valuti il tuo livello di disinvoltura nel consultare le tue registrazioni passate (umore e note)? | C8: FALSE | D8: FALSE | E8: FALSE | F8: FALSE | G8: TRUE | H8: =IF(C8=TRUE,1,0) + IF(D8=TRUE,2,0) + IF(E8=TRUE,3,0) + IF(F8=TRUE,4,0) + IF(G8=TRUE,5,0) -> 5
A9: T5_SE2 | B9: Come valuti la tua abilità nel trovare specifiche informazioni o note all'interno delle tue registrazioni passate? | C9: FALSE | D9: FALSE | E9: FALSE | F9: TRUE | G9: FALSE | H9: =IF(C9=TRUE,1,0) + IF(D9=TRUE,2,0) + IF(E9=TRUE,3,0) + IF(F9=TRUE,4,0) + IF(G9=TRUE,5,0) -> 4
A10: T6_SE1 | B10: Come valuti il tuo livello di disinvoltura nell'accedere e guardare i grafici e le sintesi dei tuoi dati? | C10: FALSE | D10: FALSE | E10: FALSE | F10: TRUE | G10: FALSE | H10: =IF(C10=TRUE,1,0) + IF(D10=TRUE,2,0) + IF(E10=TRUE,3,0) + IF(F10=TRUE,4,0) + IF(G10=TRUE,5,0) -> 4
A11: T6_SE2 | B11: Come valuti la tua abilità nell'interpretare correttamente le informazioni presentate nei grafici e nelle sintesi? | C11: FALSE | D11: FALSE | E11: FALSE | F11: TRUE | G11: FALSE | H11: =IF(C11=TRUE,1,0) + IF(D11=TRUE,2,0) + IF(E11=TRUE,3,0) + IF(F11=TRUE,4,0) + IF(G11=TRUE,5,0) -> 4
A12: T7_SE1 | B12: Come valuti il tuo livello di disinvoltura nell'utilizzare le brevi pratiche guidate (es. respirazione, mindfulness)? | C12: FALSE | D12: FALSE | E12: FALSE | F12: FALSE | G12: TRUE | H12: =IF(C12=TRUE,1,0) + IF(D12=TRUE,2,0) + IF(E12=TRUE,3,0) + IF(F12=TRUE,4,0) + IF(G12=TRUE,5,0) -> 5
A13: T7_SE2 | B13: Come valuti la tua abilità nel seguire le istruzioni e completare efficacemente gli esercizi brevi proposti? | C13: FALSE | D13: FALSE | E13: FALSE | F13: FALSE | G13: TRUE | H13: =IF(C13=TRUE,1,0) + IF(D13=TRUE,2,0) + IF(E13=TRUE,3,0) + IF(F13=TRUE,4,0) + IF(G13=TRUE,5,0) -> 5
B14: Knowledge&Skills | C14: FALSE | D14: FALSE | E14: FALSE | F14: FALSE | G14: FALSE | H14: =IF(C14=TRUE,1,0) + IF(D14=TRUE,2,0) + IF(E14=TRUE,3,0) + IF(F14=TRUE,4,0) + IF(G14=TRUE,5,0) -> 0
A15: T1_KS1 | B15: Che livello di conoscenza hai su come creare un account e impostare le preferenze iniziali nell'app? | C15: FALSE | D15: FALSE | E15: FALSE | F15: FALSE | G15: TRUE | H15: =IF(C15=TRUE,1,0) + IF(D15=TRUE,2,0) + IF(E15=TRUE,3,0) + IF(F15=TRUE,4,0) + IF(G15=TRUE,5,0) -> 5
