Workbook

Sheet BEHAVIOURABILITY
B1: Decision Making | C1: Self-Management | D1: Engagement
A2: T1 Rionoscere l'episodio | B2: K&S | D2: MOT
A3: T2 Passi immediati | B3: K&S | C3: SE | D3: MOT
A4: T3 Documentare in sicurezza | B4: K&S, PC | C4: SE | D4: MOT
A5: T4 Segnalare (anche anonimo) | B5: K&S, PC | C5: SE | D5: MOT
A6: T5 Contattare referenti/servizi | B6: K&S | C6: SE | D6: MOT
A7: T6 Supporto alla persona | B7: K&S | C7: SE | D7: MOT
A8: T7 Follow-up del caso | B8: K&S, PC | C8: SE | D8: MOT
A9: T8 Aggregare per prevenzi. | B9: K&S, PC | C9: SE | D9: MOT
A11: SE = Self-Efficacy
A12: K&S = Knowledge & Skills
A13: PC = Personal Control
A14: MOT = Motivation

Sheet Quest.Utente1
B1: Self Efficacy | C1: Scarso | D1: Sufficiente | E1: Buono | F1: Molto Buono | G1: Eccellente | H1: Valore
A2: T1_SE1 | B2: Quanto ti senti in grado di usare HumanUnity per riconoscere se un episodio è una possibile discriminazione? | C2: FALSE | D2: FALSE | E2: TRUE | F2: FALSE | G2: FALSE | H2: =IF(C2,1,0) + IF(D2,2,0) + IF(E2,3,0) + IF(F2,4,0) + IF(G2,5,0) -> 3
A3: T2_SE2 | B3: Quanto ti senti capace di seguire i passi immediati suggeriti da HumanUnity dopo un episodio? | C3: FALSE | D3: FALSE | E3: FALSE | F3: TRUE | G3: FALSE | H3: =IF(C3,1,0) + IF(D3,2,0) + IF(E3,3,0) + IF(F3,4,0) + IF(G3,5,0) -> 4
A4: T3_SE1 | B4: Quanto ti senti in grado di documentare in modo chiaro cosa è successo usando HumanUnity (dove, quando, cosa)? | C4: FALSE | D4: FALSE | E4: FALSE | F4: TRUE | G4: FALSE | H4: =IF(C4,1,0) + IF(D4,2,0) + IF(E4,3,0) + IF(F4,4,0) + IF(G4,5,0) -> 4
A5: T4_SE1 | B5: Quanto ti senti in grado di completare una segnalazione (anche anonima) tramite HumanUnity? | C5: FALSE | D5: FALSE | E5: FALSE | F5: TRUE | G5: FALSE | H5: =IF(C5,1,0) + IF(D5,2,0) + IF(E5,3,0) + IF(F5,4,0) + IF(G5,5,0) -> 4
A6: T5_SE1 | B6: Quanto ti senti capace di usare HumanUnity per contattare i referenti o i servizi giusti (sportello, UNAR, ecc.)? | C6: FALSE | D6: FALSE | E6: FALSE | F6: TRUE | G6: FALSE | H6: =IF(C6,1,0) + IF(D6,2,0) + IF(E6,3,0) + IF(F6,4,0) + IF(G6,5,0) -> 4
A7: T6_SE1 | B7: Quanto ti senti in grado di usare HumanUnity per trovare indicazioni su come supportare la persona coinvolta? | C7: FALSE | D7: FALSE | E7: FALSE | F7: FALSE | G7: TRUE | H7: =IF(C7,1,0) + IF(D7,2,0) + IF(E7,3,0) + IF(F7,4,0) + IF(G7,5,0) -> 5
A8: T7_SE1 | B8: Quanto ti senti in grado di seguire il follow-up di un caso e capire a che punto è dalla sezione “I tuoi casi”? | C8: FALSE | D8: FALSE | E8: TRUE | F8: FALSE | G8: FALSE | H8: =IF(C8,1,0) + IF(D8,2,0) + IF(E8,3,0) + IF(F8,4,0) + IF(G8,5,0) -> 3
A9: T8_SE1 | B9: Quanto ti senti capace di capire, tramite HumanUnity, se ci sono pattern ricorrenti di episodi nell’ateneo? | C9: FALSE | D9: FALSE | E9: TRUE | F9: FALSE | G9: FALSE | H9: =IF(C9,1,0) + IF(D9,2,0) + IF(E9,3,0) + IF(F9,4,0) + IF(G9,5,0) -> 3
B10: Knowledge&Skills | C10: FALSE | D10: FALSE | E10: FALSE | F10: FALSE | G10: FALSE | H10: =IF(C10=TRUE,1,0) + IF(D10=TRUE,2,0) + IF(E10=TRUE,3,0) + IF(F10=TRUE,4,0) + IF(G10=TRUE,5,0) -> 0
A11: T1_KS1 | B11: Quanto conosci le categorie di episodio (commenti offensivi, esclusione, minacce…) mostrate da HumanUnity nella fase iniziale? | C11: FALSE | D11: FALSE | E11: FALSE | F11: TRUE | G11: FALSE | H11: =IF(C11,1,0) + IF(D11,2,0) + IF(E11,3,0) + IF(F11,4,0) + IF(G11,5,0) -> 4
A12: T2_KS1 | B12: Quanto ti senti competente nel comprendere i passi immediati consigliati da HumanUnity dopo un episodio? | C12: FALSE | D12: FALSE | E12: FALSE | F12: FALSE | G12: TRUE | H12: =IF(C12,1,0) + IF(D12,2,0) + IF(E12,3,0) + IF(F12,4,0) + IF(G12,5,0) -> 5
A13: T3_KS1 | B13: Quanto conosci quali dettagli inserire nei campi per documentare in sicurezza luogo, data e descrizione dell’episodio? | C13: FALSE | D13: FALSE | E13: FALSE | F13: TRUE | G13: FALSE | H13: =IF(C13,1,0) + IF(D13,2,0) + IF(E13,3,0) + IF(F13,4,0) + IF(G13,5,0) -> 4
A14: T4_KS1 | B14: Quanto ti senti competente nel scegliere tra segnalazione rapida e segnalazione dettagliata in HumanUnity? | C14: FALSE | D14: FALSE | E14: TRUE | F14: FALSE | G14: FALSE | H14: =IF(C14,1,0) + IF(D14,2,0) + IF(E14,3,0) + IF(F14,4,0) + IF(G14,5,0) -> 3
A15: T5_KS1 | B15: Quanto conosci le diverse opzioni di contatto (sportello d’ateneo, UNAR, numeri utili) che il sistema propone? | C15: FALSE | D15: FALSE | E15: TRUE | F15: FALSE | G15: FALSE | H15: =IF(C15,1,0) + IF(D15,2,0) + IF(E15,3,0) + IF(F15,4,0) + IF(G15,5,0) -> 3
A16: T6_KS1 | B16: Quanto conosci le indicazioni pratiche che HumanUnity fornisce per aiutare una persona che subisce discriminazione? | C16: FALSE | D16: FALSE | E16: FALSE | F16: FALSE | G16: TRUE | H16: =IF(C16,1,0) + IF(D16,2,0) + IF(E16,3,0) + IF(F16,4,0) + IF(G16,5,0) -> 5
A17: T7_KS1 | B17: Quanto ti senti competente nel leggere lo stato di un caso (nuovo, in valutazione, chiuso) nella dashboard referenti? | C17: FALSE | D17: FALSE | E17: FALSE | F17: TRUE | G17: FALSE | H17: =IF(C17,1,0) + IF(D17,2,0) + IF(E17,3,0) + IF(F17,4,0) + IF(G17,5,0) -> 4
A18: T8_KS1 | B18: Quanto conosci il significato delle informazioni aggregate che potrebbero essere usate per la prevenzione (es. trend per corso/area)? | C18: FALSE | D18: FALSE | E18: FALSE | F18: TRUE | G18: FALSE | H18: =IF(C18,1,0) + IF(D18,2,0) + IF(E18,3,0) + IF(F18,4,0) + IF(G18,5,0) -> 4
B19: Personal Control | C19: FALSE | D19: FALSE | E19: FALSE | F19: FALSE | G19: FALSE | H19: =IF(C19=TRUE,1,0) + IF(D19=TRUE,2,0) + IF(E19=TRUE,3,0) + IF(F19=TRUE,4,0) + IF(G19=TRUE,5,0) -> 0
A20: T3_PC1 | B20: Quanto senti di avere controllo sul modo in cui i dettagli dell’episodio vengono registrati in HumanUnity? | C20: FALSE | D20: FALSE | E20: FALSE | F20: TRUE | G20: FALSE | H20: =IF(C20,1,0) + IF(D20,2,0) + IF(E20,3,0) + IF(F20,4,0) + IF(G20,5,0) -> 4
A21: T4_PC1 | B21: Quanto senti di poter decidere quali dati inserire e quale livello di anonimato usare nella segnalazione? | C21: FALSE | D21: FALSE | E21: FALSE | F21: TRUE | G21: FALSE | H21: =IF(C21,1,0) + IF(D21,2,0) + IF(E21,3,0) + IF(F21,4,0) + IF(G21,5,0) -> 4
A22: T7_PC1 | B22: Quanto senti di avere controllo sulle azioni successive (es. contatti, chiusura del caso) partendo dalla dashboard casi di HumanUnity? | C22: FALSE | D22: FALSE | E22: FALSE | F22: TRUE | G22: FALSE | H22: =IF(C22,1,0) + IF(D22,2,0) + IF(E22,3,0) + IF(F22,4,0) + IF(G22,5,0) -> 4
A23: T8_PC1 | B23: Quanto senti di avere controllo su come usare le informazioni aggregate per proporre iniziative di prevenzione nell’ateneo? | C23: FALSE | D23: FALSE | E23: FALSE | F23: TRUE | G23: FALSE | H23: =IF(C23,1,0) + IF(D23,2,0) + IF(E23,3,0) + IF(F23,4,0) + IF(G23,5,0) -> 4
B24: Motivation | C24: FALSE | D24: FALSE | E24: FALSE | F24: FALSE | G24: FALSE | H24: =IF(C24=TRUE,1,0) + IF(D24=TRUE,2,0) + IF(E24=TRUE,3,0) + IF(F24=TRUE,4,0) + IF(G24=TRUE,5,0) -> 0
A25: T1_MOT1 | B25: Quanto ti senti motivato a usare HumanUnity per chiarire se ciò che è successo è una discriminazione? | C25: FALSE | D25: FALSE | E25: FALSE | F25: FALSE | G25: TRUE | H25: =IF(C25,1,0) + IF(D25,2,0) + IF(E25,3,0) + IF(F25,4,0) + IF(G25,5,0) -> 5
A26: T2_MOT1 | B26: Quanto ti senti motivato a consultare la sezione “Cosa posso fare ora” dopo aver riconosciuto un episodio? | C26: FALSE | D26: FALSE | E26: FALSE | F26: TRUE | G26: FALSE | H26: =IF(C26,1,0) + IF(D26,2,0) + IF(E26,3,0) + IF(F26,4,0) + IF(G26,5,0) -> 4
A27: T3_MOT1 | B27: Quanto ti senti motivato a documentare l’episodio subito in HumanUnity, sapendo che potrai rivederlo in seguito? | C27: FALSE | D27: FALSE | E27: TRUE | F27: FALSE | G27: FALSE | H27: =IF(C27,1,0) + IF(D27,2,0) + IF(E27,3,0) + IF(F27,4,0) + IF(G27,5,0) -> 3
A28: T4_MOT1 | B28: Quanto ti senti motivato a inviare una segnalazione tramite HumanUnity invece di non fare nulla? | C28: FALSE | D28: FALSE | E28: FALSE | F28: FALSE | G28: TRUE | H28: =IF(C28,1,0) + IF(D28,2,0) + IF(E28,3,0) + IF(F28,4,0) + IF(G28,5,0) -> 5
A29: T5_MOT1 | B29: Quanto ti senti motivato a usare le informazioni di contatto fornite dal sistema per chiedere aiuto (sportello d’ateneo, UNAR, numeri)? | C29: FALSE | D29: FALSE | E29: FALSE | F29: TRUE | G29: FALSE | H29: =IF(C29,1,0) + IF(D29,2,0) + IF(E29,3,0) + IF(F29,4,0) + IF(G29,5,0) -> 4
A30: T6_MOT1 | B30: Quanto ti senti motivato a usare HumanUnity per sostenere un compagno che ha subito discriminazione? | C30: FALSE | D30: FALSE | E30: FALSE | F30: FALSE | G30: TRUE | H30: =IF(C30,1,0) + IF(D30,2,0) + IF(E30,3,0) + IF(F30,4,0) + IF(G30,5,0) -> 5
A31: T7_MOT1 | B31: Quanto ti senti motivato a controllare periodicamente gli aggiornamenti del tuo caso nella sezione “I tuoi casi”? | C31: FALSE | D31: FALSE | E31: FALSE | F31: TRUE | G31: FALSE | H31: =IF(C31,1,0) + IF(D31,2,0) + IF(E31,3,0) + IF(F31,4,0) + IF(G31,5,0) -> 4
A32: T8_MOT1 | B32: Quanto ti senti motivato a consultare periodicamente i dati aggregati per capire se la situazione nell’ateneo sta migliorando? | C32: FALSE | D32: FALSE | E32: TRUE | F32: FALSE | G32: FALSE | H32: =IF(C32,1,0) + IF(D32,2,0) + IF(E32,3,0) + IF(F32,4,0) + IF(G32,5,0) -> 3

Sheet MEDIE
B1: Self Efficacy | C1: Valore
A2: T1_SE1 | B2: Quanto ti senti in grado di usare HumanUnity per riconoscere se un episodio è una possibile discriminazione? | C2: =AVERAGE(Quest.Utente1!H2,Quest.Utente2!H2,Quest.Utente3!H2,Quest.Utente4!H2,Quest.Utente5!H2,Quest.Utente6!H2,Quest.Utente7!H2,Quest.Utente8!H2,Quest.Utente9!H2,Quest.Utente10!H2) -> 4.4
A3: T2_SE2 | B3: Quanto ti senti capace di seguire i passi immediati suggeriti da HumanUnity dopo un episodio? | C3: =AVERAGE(Quest.Utente1!H3,Quest.Utente2!H3,Quest.Utente3!H3,Quest.Utente4!H3,Quest.Utente5!H3,Quest.Utente6!H3,Quest.Utente7!H3,Quest.Utente8!H3,Quest.Utente9!H3,Quest.Utente10!H3) -> 4.3
A4: T3_SE1 | B4: Quanto ti senti in grado di documentare in modo chiaro cosa è successo usando HumanUnity (dove, quando, cosa)? | C4: =AVERAGE(Quest.Utente1!H4,Quest.Utente2!H4,Quest.Utente3!H4,Quest.Utente4!H4,Quest.Utente5!H4,Quest.Utente6!H4,Quest.Utente7!H4,Quest.Utente8!H4,Quest.Utente9!H4,Quest.Utente10!H4) -> 4
A5: T4_SE1 | B5: Quanto ti senti in grado di completare una segnalazione (anche anonima) tramite HumanUnity? | C5: =AVERAGE(Quest.Utente1!H5,Quest.Utente2!H5,Quest.Utente3!H5,Quest.Utente4!H5,Quest.Utente5!H5,Quest.Utente6!H5,Quest.Utente7!H5,Quest.Utente8!H5,Quest.Utente9!H5,Quest.Utente10!H5) -> 4
A6: T5_SE1 | B6: Quanto ti senti capace di usare HumanUnity per contattare i referenti o i servizi giusti (sportello, UNAR, ecc.)? | C6: =AVERAGE(Quest.Utente1!H6,Quest.Utente2!H6,Quest.Utente3!H6,Quest.Utente4!H6,Quest.Utente5!H6,Quest.Utente6!H6,Quest.Utente7!H6,Quest.Utente8!H6,Quest.Utente9!H6,Quest.Utente10!H6) -> 4.2
A7: T6_SE1 | B7: Quanto ti senti in grado di usare HumanUnity per trovare indicazioni su come supportare la persona coinvolta? | C7: =AVERAGE(Quest.Utente1!H7,Quest.Utente2!H7,Quest.Utente3!H7,Quest.Utente4!H7,Quest.Utente5!H7,Quest.Utente6!H7,Quest.Utente7!H7,Quest.Utente8!H7,Quest.Utente9!H7,Quest.Utente10!H7) -> 4
A8: T7_SE1 | B8: Quanto ti senti in grado di seguire il follow-up di un caso e capire a che punto è dalla sezione “I tuoi casi”? | C8: =AVERAGE(Quest.Utente1!H8,Quest.Utente2!H8,Quest.Utente3!H8,Quest.Utente4!H8,Quest.Utente5!H8,Quest.Utente6!H8,Quest.Utente7!H8,Quest.Utente8!H8,Quest.Utente9!H8,Quest.Utente10!H8) -> 3.9
A9: T8_SE1 | B9: Quanto ti senti capace di capire, tramite HumanUnity, se ci sono pattern ricorrenti di episodi nell’ateneo? | C9: =AVERAGE(Quest.Utente1!H9,Quest.Utente2!H9,Quest.Utente3!H9,Quest.Utente4!H9,Quest.Utente5!H9,Quest.Utente6!H9,Quest.Utente7!H9,Quest.Utente8!H9,Quest.Utente9!H9,Quest.Utente10!H9) -> 3.9
C10: =AVERAGE(C2:C9) -> 4.0875
B12: Knowledge&Skills
A13: T1_KS1 | B13: Quanto conosci le categorie di episodio (commenti offensivi, esclusione, minacce…) mostrate da HumanUnity nella fase iniziale? | C13: =AVERAGE(Quest.Utente1!H11,Quest.Utente2!H11,Quest.Utente3!H11,Quest.Utente4!H11,Quest.Utente5!H11,Quest.Utente6!H11,Quest.Utente7!H11,Quest.Utente8!H11,Quest.Utente9!H11,Quest.Utente10!H11) -> 4.2
A14: T2_KS1 | B14: Quanto ti senti competente nel comprendere i passi immediati consigliati da HumanUnity dopo un episodio? | C14: =AVERAGE(Quest.Utente1!H12,Quest.Utente2!H12,Quest.Utente3!H12,Quest.Utente4!H12,Quest.Utente5!H12,Quest.Utente6!H12,Quest.Utente7!H12,Quest.Utente8!H12,Quest.Utente9!H12,Quest.Utente10!H12) -> 4.2
A15: T3_KS1 | B15: Quanto conosci quali dettagli inserire nei campi per documentare in sicurezza luogo, data e descrizione dell’episodio? | C15: =AVERAGE(Quest.Utente1!H13,Quest.Utente2!H13,Quest.Utente3!H13,Quest.Utente4!H13,Quest.Utente5!H13,Quest.Utente6!H13,Quest.Utente7!H13,Quest.Utente8!H13,Quest.Utente9!H13,Quest.Utente10!H13) -> 3.9
A16: T4_KS1 | B16: Quanto ti senti competente nel scegliere tra segnalazione rapida e segnalazione dettagliata in HumanUnity? | C16: =AVERAGE(Quest.Utente1!H14,Quest.Utente2!H14,Quest.Utente3!H14,Quest.Utente4!H14,Quest.Utente5!H14,Quest.Utente6!H14,Quest.Utente7!H14,Quest.Utente8!H14,Quest.Utente9!H14,Quest.Utente10!H14) -> 3.9
A17: T5_KS1 | B17: Quanto conosci le diverse opzioni di contatto (sportello d’ateneo, UNAR, numeri utili) che il sistema propone? | C17: =AVERAGE(Quest.Utente1!H15,Quest.Utente2!H15,Quest.Utente3!H15,Quest.Utente4!H15,Quest.Utente5!H15,Quest.Utente6!H15,Quest.Utente7!H15,Quest.Utente8!H15,Quest.Utente9!H15,Quest.Utente10!H15) -> 3.9
A18: T6_KS1 | B18: Quanto conosci le indicazioni pratiche che HumanUnity fornisce per aiutare una persona che subisce discriminazione? | C18: =AVERAGE(Quest.Utente1!H16,Quest.Utente2!H16,Quest.Utente3!H16,Quest.Utente4!H16,Quest.Utente5!H16,Quest.Utente6!H16,Quest.Utente7!H16,Quest.Utente8!H16,Quest.Utente9!H16,Quest.Utente10!H16) -> 3.9
A19: T7_KS1 | B19: Quanto ti senti competente nel leggere lo stato di un caso (nuovo, in valutazione, chiuso) nella dashboard referenti? | C19: =AVERAGE(Quest.Utente1!H17,Quest.Utente2!H17,Quest.Utente3!H17,Quest.Utente4!H17,Quest.Utente5!H17,Quest.Utente6!H17,Quest.Utente7!H17,Quest.Utente8!H17,Quest.Utente9!H17,Quest.Utente10!H17) -> 3.7
A20: T8_KS1 | B20: Quanto conosci il significato delle informazioni aggregate che potrebbero essere usate per la prevenzione (es. trend per corso/area)? | C20: =AVERAGE(Quest.Utente1!H18,Quest.Utente2!H18,Quest.Utente3!H18,Quest.Utente4!H18,Quest.Utente5!H18,Quest.Utente6!H18,Quest.Utente7!H18,Quest.Utente8!H18,Quest.Utente9!H18,Quest.Utente10!H18) -> 3.8
C21: =AVERAGE(C13:C20) -> 3.9375
B23: Personal Control
A24: T3_PC1 | B24: Quanto senti di avere controllo sul modo in cui i dettagli dell’episodio vengono registrati in HumanUnity? | C24: =AVERAGE(Quest.Utente1!H20,Quest.Utente2!H20,Quest.Utente3!H20,Quest.Utente4!H20,Quest.Utente5!H20,Quest.Utente6!H20,Quest.Utente7!H20,Quest.Utente8!H20,Quest.Utente9!H20,Quest.Utente10!H20) -> 3.7
A25: T4_PC1 | B25: Quanto senti di poter decidere quali dati inserire e quale livello di anonimato usare nella segnalazione? | C25: =AVERAGE(Quest.Utente1!H21,Quest.Utente2!H21,Quest.Utente3!H21,Quest.Utente4!H21,Quest.Utente5!H21,Quest.Utente6!H21,Quest.Utente7!H21,Quest.Utente8!H21,Quest.Utente9!H21,Quest.Utente10!H21) -> 3.6
A26: T7_PC1 | B26: Quanto senti di avere controllo sulle azioni successive (es. contatti, chiusura del caso) partendo dalla dashboard casi di HumanUnity? | C26: =AVERAGE(Quest.Utente1!H22,Quest.Utente2!H22,Quest.Utente3!H22,Quest.Utente4!H22,Quest.Utente5!H22,Quest.Utente6!H22,Quest.Utente7!H22,Quest.Utente8!H22,Quest.Utente9!H22,Quest.Utente10!H22) -> 4
A27: T8_PC1 | B27: Quanto senti di avere controllo su come usare le informazioni aggregate per proporre iniziative di prevenzione nell’ateneo? | C27: =AVERAGE(Quest.Utente1!H23,Quest.Utente2!H23,Quest.Utente3!H23,Quest.Utente4!H23,Quest.Utente5!H23,Quest.Utente6!H23,Quest.Utente7!H23,Quest.Utente8!H23,Quest.Utente9!H23,Quest.Utente10!H23) -> 3.5
C28: =AVERAGE(C24:C27) -> 3.7
B30: Motivation
A31: T1_MOT1 | B31: Quanto ti senti motivato a usare HumanUnity per chiarire se ciò che è successo è una discriminazione? | C31: =AVERAGE(Quest.Utente1!H25,Quest.Utente2!H25,Quest.Utente3!H25,Quest.Utente4!H25,Quest.Utente5!H25,Quest.Utente6!H25,Quest.Utente7!H25,Quest.Utente8!H25,Quest.Utente9!H25,Quest.Utente10!H25) -> 4.2
A32: T2_MOT1 | B32: Quanto ti senti motivato a consultare la sezione “Cosa posso fare ora” dopo aver riconosciuto un episodio? | C32: =AVERAGE(Quest.Utente1!H26,Quest.Utente2!H26,Quest.Utente3!H26,Quest.Utente4!H26,Quest.Utente5!H26,Quest.Utente6!H26,Quest.Utente7!H26,Quest.Utente8!H26,Quest.Utente9!H26,Quest.Utente10!H26) -> 4.2
A33: T3_MOT1 | B33: Quanto ti senti motivato a documentare l’episodio subito in HumanUnity, sapendo che potrai rivederlo in seguito? | C33: =AVERAGE(Quest.Utente1!H27,Quest.Utente2!H27,Quest.Utente3!H27,Quest.Utente4!H27,Quest.Utente5!H27,Quest.Utente6!H27,Quest.Utente7!H27,Quest.Utente8!H27,Quest.Utente9!H27,Quest.Utente10!H27) -> 4
A34: T4_MOT1 | B34: Quanto ti senti motivato a inviare una segnalazione tramite HumanUnity invece di non fare nulla? | C34: =AVERAGE(Quest.Utente1!H28,Quest.Utente2!H28,Quest.Utente3!H28,Quest.Utente4!H28,Quest.Utente5!H28,Quest.Utente6!H28,Quest.Utente7!H28,Quest.Utente8!H28,Quest.Utente9!H28,Quest.Utente10!H28) -> 4.1
A35: T5_MOT1 | B35: Quanto ti senti motivato a usare le informazioni di contatto fornite dal sistema per chiedere aiuto (sportello d’ateneo, UNAR, numeri)? | C35: =AVERAGE(Quest.Utente1!H29,Quest.Utente2!H29,Quest.Utente3!H29,Quest.Utente4!H29,Quest.Utente5!H29,Quest.Utente6!H29,Quest.Utente7!H29,Quest.Utente8!H29,Quest.Utente9!H29,Quest.Utente10!H29) -> 4.2
A36: T6_MOT1 | B36: Quanto ti senti motivato a usare HumanUnity per sostenere un compagno che ha subito discriminazione? | C36: =AVERAGE(Quest.Utente1!H30,Quest.Utente2!H30,Quest.Utente3!H30,Quest.Utente4!H30,Quest.Utente5!H30,Quest.Utente6!H30,Quest.Utente7!H30,Quest.Utente8!H30,Quest.Utente9!H30,Quest.Utente10!H30) -> 4
A37: T7_MOT1 | B37: Quanto ti senti motivato a controllare periodicamente gli aggiornamenti del tuo caso nella sezione “I tuoi casi”? | C37: =AVERAGE(Quest.Utente1!H31,Quest.Utente2!H31,Quest.Utente3!H31,Quest.Utente4!H31,Quest.Utente5!H31,Quest.Utente6!H31,Quest.Utente7!H31,Quest.Utente8!H31,Quest.Utente9!H31,Quest.Utente10!H31) -> 3.8
A38: T8_MOT1 | B38: Quanto ti senti motivato a consultare periodicamente i dati aggregati per capire se la situazione nell’ateneo sta migliorando? | C38: =AVERAGE(Quest.Utente1!H32,Quest.Utente2!H32,Quest.Utente3!H32,Quest.Utente4!H32,Quest.Utente5!H32,Quest.Utente6!H32,Quest.Utente7!H32,Quest.Utente8!H32,Quest.Utente9!H32,Quest.Utente10!H32) -> 3.9
C39: =AVERAGE(C31:C38) -> 4.05

Sheet TabRisultati
A1: Task | B1: ISE | C1: IKS | D1: IPC | E1: IMOT
A2: T1 Rionoscere l'episodio | B2: =MEDIE!C2 -> 4.4 | C2: =MEDIE!C13 -> 4.2 | D2: 0 | E2: =MEDIE!C31 -> 4.2
A3: T2 Passi immediati | B3: =MEDIE!C3 -> 4.3 | C3: =MEDIE!C14 -> 4.2 | D3: 0 | E3: =MEDIE!C32 -> 4.2
A4: T3 Documentare in sicurezza | B4: =MEDIE!C4 -> 4 | C4: =MEDIE!C15 -> 3.9 | D4: =MEDIE!C24 -> 3.7 | E4: =MEDIE!C33 -> 4
A5: T4 Segnalare (anche anonimo) | B5: =MEDIE!C5 -> 4 | C5: =MEDIE!C16 -> 3.9 | D5: =MEDIE!C25 -> 3.6 | E5: =MEDIE!C34 -> 4.1
A6: T5 Contattare referenti/servizi | B6: =MEDIE!C6 -> 4.2 | C6: =MEDIE!C17 -> 3.9 | D6: 0 | E6: =MEDIE!C35 -> 4.2
A7: T6 Supporto alla persona | B7: =MEDIE!C7 -> 4 | C7: =MEDIE!C18 -> 3.9 | D7: 0 | E7: =MEDIE!C36 -> 4
A8: T7 Follow-up del caso | B8: =MEDIE!C8 -> 3.9 | C8: =MEDIE!C19 -> 3.7 | D8: =MEDIE!C26 -> 4 | E8: =MEDIE!C37 -> 3.8
A9: T8 Aggregare per prevenzi. | B9: =MEDIE!C9 -> 3.9 | C9: =MEDIE!C20 -> 3.8 | D9: =MEDIE!C27 -> 3.5 | E9: =MEDIE!C38 -> 3.9
A11: LEGENDA:
A12: Critico (< 3.6) | B12: < 3.6
A13: Attenzione (3.6-3.69) | B13: 3.6-3.69

Sheet Quest.Utente2
B1: Self Efficacy | C1: Scarso | D1: Sufficiente | E1: Buono | F1: Molto Buono | G1: Eccellente | H1: Valore
A2: T1_SE1 | B2: Quanto ti senti in grado di usare HumanUnity per riconoscere se un episodio è una possibile discriminazione? | C2: FALSE | D2: FALSE | E2: FALSE | F2: FALSE | G2: TRUE | H2: =IF(C2,1,0) + IF(D2,2,0) + IF(E2,3,0) + IF(F2,4,0) + IF(G2,5,0) -> 5
A3: T2_SE2 | B3: Quanto ti senti capace di seguire i passi immediati suggeriti da HumanUnity dopo un episodio? | C3: FALSE | D3: FALSE | E3: FALSE | F3: FALSE | G3: TRUE | H3: =IF(C3,1,0) + IF(D3,2,0) + IF(E3,3,0) + IF(F3,4,0) + IF(G3,5,0) -> 5
A4: T3_SE1 | B4: Quanto ti senti in grado di documentare in modo chiaro cosa è successo usando HumanUnity (dove, quando, cosa)? | C4: FALSE | D4: FALSE | E4: TRUE | F4: FALSE | G4: FALSE | H4: =IF(C4,1,0) + IF(D4,2,0) + IF(E4,3,0) + IF(F4,4,0) + IF(G4,5,0) -> 3
A5: T4_SE1 | B5: Quanto ti senti in grado di completare una segnalazione (anche anonima) tramite HumanUnity? | C5: FALSE | D5: FALSE | E5: FALSE | F5: TRUE | G5: FALSE | H5: =IF(C5,1,0) + IF(D5,2,0) + IF(E5,3,0) + IF(F5,4,0) + IF(G5,5,0) -> 4
A6: T5_SE1 | B6: Quanto ti senti capace di usare HumanUnity per contattare i referenti o i servizi giusti (sportello, UNAR, ecc.)? | C6: FALSE | D6: FALSE | E6: FALSE | F6: TRUE | G6: FALSE | H6: =IF(C6,1,0) + IF(D6,2,0) + IF(E6,3,0) + IF(F6,4,0) + IF(G6,5,0) -> 4
A7: T6_SE1 | B7: Quanto ti senti in grado di usare HumanUnity per trovare indicazioni su come supportare la persona coinvolta? | C7: FALSE | D7: FALSE | E7: TRUE | F7: FALSE | G7: FALSE | H7: =IF(C7,1,0) + IF(D7,2,0) + IF(E7,3,0) + IF(F7,4,0) + IF(G7,5,0) -> 3
A8: T7_SE1 | B8: Quanto ti senti in grado di seguire il follow-up di un caso e capire a che punto è dalla sezione “I tuoi casi”? | C8: FALSE | D8: TRUE | E8: FALSE | F8: FALSE | G8: FALSE | H8: =IF(C8,1,0) + IF(D8,2,0) + IF(E8,3,0) + IF(F8,4,0) + IF(G8,5,0) -> 2
A9: T8_SE1 | B9: Quanto ti senti capace di capire, tramite HumanUnity, se ci sono pattern ricorrenti di episodi nell’ateneo? | C9: FALSE | D9: FALSE | E9: TRUE | F9: FALSE | G9: FALSE | H9: =IF(C9,1,0) + IF(D9,2,0) + IF(E9,3,0) + IF(F9,4,0) + IF(G9,5,0) -> 3
B10: Knowledge&Skills | C10: FALSE | D10: FALSE | E10: FALSE | F10: FALSE | G10: FALSE | H10: =IF(C10=TRUE,1,0) + IF(D10=TRUE,2,0) + IF(E10=TRUE,3,0) + IF(F10=TRUE,4,0) + IF(G10=TRUE,5,0) -> 0
A11: T1_KS1 | B11: Quanto conosci le categorie di episodio (commenti offensivi, esclusione, minacce…) mostrate da HumanUnity nella fase iniziale? | C11: FALSE | D11: FALSE | E11: FALSE | F11: TRUE | G11: FALSE | H11: =IF(C11,1,0) + IF(D11,2,0) + IF(E11,3,0) + IF(F11,4,0) + IF(G11,5,0) -> 4
A12: T2_KS1 | B12: Quanto ti senti competente nel comprendere i passi immediati consigliati da HumanUnity dopo un episodio? | C12: FALSE | D12: FALSE | E12: FALSE | F12: TRUE | G12: FALSE | H12: =IF(C12,1,0) + IF(D12,2,0) + IF(E12,3,0) + IF(F12,4,0) + IF(G12,5,0) -> 4
A13: T3_KS1 | B13: Quanto conosci quali dettagli inserire nei campi per documentare in sicurezza luogo, data e descrizione dell’episodio? | C13: FALSE | D13: FALSE | E13: FALSE | F13: FALSE | G13: TRUE | H13: =IF(C13,1,0) + IF(D13,2,0) + IF(E13,3,0) + IF(F13,4,0) + IF(G13,5,0) -> 5
A14: T4_KS1 | B14: Quanto ti senti competente nel scegliere tra segnalazione rapida e segnalazione dettagliata in HumanUnity? | C14: FALSE | D14: FALSE | E14: FALSE | F14: TRUE | G14: FALSE | H14: =IF(C14,1,0) + IF(D14,2,0) + IF(E14,3,0) + IF(F14,4,0) + IF(G14,5,0) -> 4
A15: T5_KS1 | B15: Quanto conosci le diverse opzioni di contatto (sportello d’ateneo, UNAR, numeri utili) che il sistema propone? | C15: FALSE | D15: FALSE | E15: FALSE | F15: TRUE | G15: FALSE | H15: =IF(C15,1,0) + IF(D15,2,0) + IF(E15,3,0) + IF(F15,4,0) + IF(G15,5,0) -> 4
A16: T6_KS1 | B16: Quanto conosci le indicazioni pratiche che HumanUnity fornisce per aiutare una persona che subisce discriminazione? | C16: FALSE | D16: FALSE | E16: FALSE | F16: TRUE | G16: FALSE | H16: =IF(C16,1,0) + IF(D16,2,0) + IF(E16,3,0) + IF(F16,4,0) + IF(G16,5,0) -> 4
A17: T7_KS1 | B17: Quanto ti senti competente nel leggere lo stato di un caso (nuovo, in valutazione, chiuso) nella dashboard referenti? | C17: FALSE | D17: FALSE | E17: TRUE | F17: FALSE | G17: FALSE | H17: =IF(C17,1,0) + IF(D17,2,0) + IF(E17,3,0) + IF(F17,4,0) + IF(G17,5,0) -> 3
A18: T8_KS1 | B18: Quanto conosci il significato delle informazioni aggregate che potrebbero essere usate per la prevenzione (es. trend per corso/area)? | C18: FALSE | D18: FALSE | E18: TRUE | F18: FALSE | G18: FALSE | H18: =IF(C18,1,0) + IF(D18,2,0) + IF(E18,3,0) + IF(F18,4,0) + IF(G18,5,0) -> 3
B19: Personal Control | C19: FALSE | D19: FALSE | E19: FALSE | F19: FALSE | G19: FALSE | H19: =IF(C19=TRUE,1,0) + IF(D19=TRUE,2,0) + IF(E19=TRUE,3,0) + IF(F19=TRUE,4,0) + IF(G19=TRUE,5,0) -> 0
A20: T3_PC1 | B20: Quanto senti di avere controllo sul modo in cui i dettagli dell’episodio vengono registrati in HumanUnity? | C20: FALSE | D20: FALSE | E20: FALSE | F20: TRUE | G20: FALSE | H20: =IF(C20,1,0) + IF(D20,2,0) + IF(E20,3,0) + IF(F20,4,0) + IF(G20,5,0) -> 4
A21: T4_PC1 | B21: Quanto senti di poter decidere quali dati inserire e quale livello di anonimato usare nella segnalazione? | C21: FALSE | D21: FALSE | E21: TRUE | F21: FALSE | G21: FALSE | H21: =IF(C21,1,0) + IF(D21,2,0) + IF(E21,3,0) + IF(F21,4,0) + IF(G21,5,0) -> 3
A22: T7_PC1 | B22: Quanto senti di avere controllo sulle azioni successive (es. contatti, chiusura del caso) partendo dalla dashboard casi di HumanUnity? | C22: FALSE | D22: FALSE | E22: FALSE | F22: TRUE | G22: FALSE | H22: =IF(C22,1,0) + IF(D22,2,0) + IF(E22,3,0) + IF(F22,4,0) + IF(G22,5,0) -> 4
A23: T8_PC1 | B23: Quanto senti di avere controllo su come usare le informazioni aggregate per proporre iniziative di prevenzione nell’ateneo? | C23: FALSE | D23: FALSE | E23: FALSE | F23: TRUE | G23: FALSE | H23: =IF(C23,1,0) + IF(D23,2,0) + IF(E23,3,0) + IF(F23,4,0) + IF(G23,5,0) -> 4
B24: Motivation | C24: FALSE | D24: FALSE | E24: FALSE | F24: FALSE | G24: FALSE | H24: =IF(C24=TRUE,1,0) + IF(D24=TRUE,2,0) + IF(E24=TRUE,3,0) + IF(F24=TRUE,4,0) + IF(G24=TRUE,5,0) -> 0
A25: T1_MOT1 | B25: Quanto ti senti motivato a usare HumanUnity per chiarire se ciò che è successo è una discriminazione? | C25: FALSE | D25: FALSE | E25: TRUE | F25: FALSE | G25: FALSE | H25: =IF(C25,1,0) + IF(D25,2,0) + IF(E25,3,0) + IF(F25,4,0) + IF(G25,5,0) -> 3
A26: T2_MOT1 | B26: Quanto ti senti motivato a consultare la sezione “Cosa posso fare ora” dopo aver riconosciuto un episodio? | C26: FALSE | D26: FALSE | E26: FALSE | F26: FALSE | G26: TRUE | H26: =IF(C26,1,0) + IF(D26,2,0) + IF(E26,3,0) + IF(F26,4,0) + IF(G26,5,0) -> 5
A27: T3_MOT1 | B27: Quanto ti senti motivato a documentare l’episodio subito in HumanUnity, sapendo che potrai rivederlo in seguito? | C27: FALSE | D27: FALSE | E27: FALSE | F27: FALSE | G27: TRUE | H27: =IF(C27,1,0) + IF(D27,2,0) + IF(E27,3,0) + IF(F27,4,0) + IF(G27,5,0) -> 5
A28: T4_MOT1 | B28: Quanto ti senti motivato a inviare una segnalazione tramite HumanUnity invece di non fare nulla? | C28: FALSE | D28: FALSE | E28: FALSE | F28: TRUE | G28: FALSE | H28: =IF(C28,1,0) + IF(D28,2,0) + IF(E28,3,0) + IF(F28,4,0) + IF(G28,5,0) -> 4
A29: T5_MOT1 | B29: Quanto ti senti motivato a usare le informazioni di contatto fornite dal sistema per chiedere aiuto (sportello d’ateneo, UNAR, numeri)? | C29: FALSE | D29: FALSE | E29: FALSE | F29: TRUE | G29: FALSE | H29: =IF(C29,1,0) + IF(D29,2,0) + IF(E29,3,0) + IF(F29,4,0) + IF(G29,5,0) -> 4
A30: T6_MOT1 | B30: Quanto ti senti motivato a usare HumanUnity per sostenere un compagno che ha subito discriminazione? | C30: FALSE | D30: FALSE | E30: FALSE | F30: TRUE | G30: FALSE | H30: =IF(C30,1,0) + IF(D30,2,0) + IF(E30,3,0) + IF(F30,4,0) + IF(G30,5,0) -> 4
A31: T7_MOT1 | B31: Quanto ti senti motivato a controllare periodicamente gli aggiornamenti del tuo caso nella sezione “I tuoi casi”? | C31: FALSE | D31: FALSE | E31: TRUE | F31: FALSE | G31: FALSE | H31: =IF(C31,1,0) + IF(D31,2,0) + IF(E31,3,0) + IF(F31,4,0) + IF(G31,5,0) -> 3
A32: T8_MOT1 | B32: Quanto ti senti motivato a consultare periodicamente i dati aggregati per capire se la situazione nell’ateneo sta migliorando? | C32: FALSE | D32: FALSE | E32: FALSE | F32: TRUE | G32: FALSE | H32: =IF(C32,1,0) + IF(D32,2,0) + IF(E32,3,0) + IF(F32,4,0) + IF(G32,5,0) -> 4

Sheet Quest.Utente3
B1: Self Efficacy | C1: Scarso | D1: Sufficiente | E1: Buono | F1: Molto Buono | G1: Eccellente | H1: Valore
A2: T1_SE1 | B2: Quanto ti senti in grado di usare HumanUnity per riconoscere se un episodio è una possibile discriminazione? | C2: FALSE | D2: FALSE | E2: FALSE | F2: FALSE | G2: TRUE | H2: =IF(C2,1,0) + IF(D2,2,0) + IF(E2,3,0) + IF(F2,4,0) + IF(G2,5,0) -> 5
A3: T2_SE2 | B3: Quanto ti senti capace di seguire i passi immediati suggeriti da HumanUnity dopo un episodio? | C3: FALSE | D3: FALSE | E3: FALSE | F3: TRUE | G3: FALSE | H3: =IF(C3,1,0) + IF(D3,2,0) + IF(E3,3,0) + IF(F3,4,0) + IF(G3,5,0) -> 4
A4: T3_SE1 | B4: Quanto ti senti in grado di documentare in modo chiaro cosa è successo usando HumanUnity (dove, quando, cosa)? | C4: FALSE | D4: FALSE | E4: FALSE | F4: TRUE | G4: FALSE | H4: =IF(C4,1,0) + IF(D4,2,0) + IF(E4,3,0) + IF(F4,4,0) + IF(G4,5,0) -> 4
A5: T4_SE1 | B5: Quanto ti senti in grado di completare una segnalazione (anche anonima) tramite HumanUnity? | C5: FALSE | D5: FALSE | E5: FALSE | F5: FALSE | G5: TRUE | H5: =IF(C5,1,0) + IF(D5,2,0) + IF(E5,3,0) + IF(F5,4,0) + IF(G5,5,0) -> 5
A6: T5_SE1 | B6: Quanto ti senti capace di usare HumanUnity per contattare i referenti o i servizi giusti (sportello, UNAR, ecc.)? | C6: FALSE | D6: FALSE | E6: FALSE | F6: TRUE | G6: FALSE | H6: =IF(C6,1,0) + IF(D6,2,0) + IF(E6,3,0) + IF(F6,4,0) + IF(G6,5,0) -> 4
A7: T6_SE1 | B7: Quanto ti senti in grado di usare HumanUnity per trovare indicazioni su come supportare la persona coinvolta? | C7: FALSE | D7: FALSE | E7: FALSE | F7: TRUE | G7: FALSE | H7: =IF(C7,1,0) + IF(D7,2,0) + IF(E7,3,0) + IF(F7,4,0) + IF(G7,5,0) -> 4
A8: T7_SE1 | B8: Quanto ti senti in grado di seguire il follow-up di un caso e capire a che punto è dalla sezione “I tuoi casi”? | C8: FALSE | D8: FALSE | E8: FALSE | F8: TRUE | G8: FALSE | H8: =IF(C8,1,0) + IF(D8,2,0) + IF(E8,3,0) + IF(F8,4,0) + IF(G8,5,0) -> 4
A9: T8_SE1 | B9: Quanto ti senti capace di capire, tramite HumanUnity, se ci sono pattern ricorrenti di episodi nell’ateneo? | C9: FALSE | D9: FALSE | E9: FALSE | F9: TRUE | G9: FALSE | H9: =IF(C9,1,0) + IF(D9,2,0) + IF(E9,3,0) + IF(F9,4,0) + IF(G9,5,0) -> 4
B10: Knowledge&Skills | C10: FALSE | D10: FALSE | E10: FALSE | F10: FALSE | G10: FALSE | H10: =IF(C10=TRUE,1,0) + IF(D10=TRUE,2,0) + IF(E10=TRUE,3,0) + IF(F10=TRUE,4,0) + IF(G10=TRUE,5,0) -> 0
A11: T1_KS1 | B11: Quanto conosci le categorie di episodio (commenti offensivi, esclusione, minacce…) mostrate da HumanUnity nella fase iniziale? | C11: FALSE | D11: FALSE | E11: FALSE | F11: TRUE | G11: FALSE | H11: =IF(C11,1,0) + IF(D11,2,0) + IF(E11,3,0) + IF(F11,4,0) + IF(G11,5,0) -> 4
A12: T2_KS1 | B12: Quanto ti senti competente nel comprendere i passi immediati consigliati da HumanUnity dopo un episodio? | C12: FALSE | D12: FALSE | E12: FALSE | F12: TRUE | G12: FALSE | H12: =IF(C12,1,0) + IF(D12,2,0) + IF(E12,3,0) + IF(F12,4,0) + IF(G12,5,0) -> 4
A13: T3_KS1 | B13: Quanto conosci quali dettagli inserire nei campi per documentare in sicurezza luogo, data e descrizione dell’episodio? | C13: FALSE | D13: FALSE | E13: FALSE | F13: FALSE | G13: TRUE | H13: =IF(C13,1,0) + IF(D13,2,0) + IF(E13,3,0) + IF(F13,4,0) + IF(G13,5,0) -> 5
A14: T4_KS1 | B14: Quanto ti senti competente nel scegliere tra segnalazione rapida e segnalazione dettagliata in HumanUnity? | C14: FALSE | D14: TRUE | E14: FALSE | F14: FALSE | G14: FALSE | H14: =IF(C14,1,0) + IF(D14,2,0) + IF(E14,3,0) + IF(F14,4,0) + IF(G14,5,0) -> 2
A15: T5_KS1 | B15: Quanto conosci le diverse opzioni di contatto (sportello d’ateneo, UNAR, numeri utili) che il sistema propone? | C15: FALSE | D15: FALSE | E15: FALSE | F15: TRUE | G15: FALSE | H15: =IF(C15,1,0) + IF(D15,2,0) + IF(E15,3,0) + IF(F15,4,0) + IF(G15,5,0) -> 4
A16: T6_KS1 | B16: Quanto conosci le indicazioni pratiche che HumanUnity fornisce per aiutare una persona che subisce discriminazione? | C16: FALSE | D16: FALSE | E16: FALSE | F16: TRUE | G16: FALSE | H16: =IF(C16,1,0) + IF(D16,2,0) + IF(E16,3,0) + IF(F16,4,0) + IF(G16,5,0) -> 4
A17: T7_KS1 | B17: Quanto ti senti competente nel leggere lo stato di un caso (nuovo, in valutazione, chiuso) nella dashboard referenti? | C17: FALSE | D17: FALSE | E17: FALSE | F17: TRUE | G17: FALSE | H17: =IF(C17,1,0) + IF(D17,2,0) + IF(E17,3,0) + IF(F17,4,0) + IF(G17,5,0) -> 4
A18: T8_KS1 | B18: Quanto conosci il significato delle informazioni aggregate che potrebbero essere usate per la prevenzione (es. trend per corso/area)? | C18: FALSE | D18: FALSE | E18: FALSE | F18: FALSE | G18: TRUE | H18: =IF(C18,1,0) + IF(D18,2,0) + IF(E18,3,0) + IF(F18,4,0) + IF(G18,5,0) -> 5
B19: Personal Control | C19: FALSE | D19: FALSE | E19: FALSE | F19: FALSE | G19: FALSE | H19: =IF(C19=TRUE,1,0) + IF(D19=TRUE,2,0) + IF(E19=TRUE,3,0) + IF(F19=TRUE,4,0) + IF(G19=TRUE,5,0) -> 0
A20: T3_PC1 | B20: Quanto senti di avere controllo sul modo in cui i dettagli dell’episodio vengono registrati in HumanUnity? | C20: FALSE | D20: FALSE | E20: FALSE | F20: TRUE | G20: FALSE | H20: =IF(C20,1,0) + IF(D20,2,0) + IF(E20,3,0) + IF(F20,4,0) + IF(G20,5,0) -> 4
A21: T4_PC1 | B21: Quanto senti di poter decidere quali dati inserire e quale livello di anonimato usare nella segnalazione? | C21: FALSE | D21: FALSE | E21: FALSE | F21: FALSE | G21: TRUE | H21: =IF(C21,1,0) + IF(D21,2,0) + IF(E21,3,0) + IF(F21,4,0) + IF(G21,5,0) -> 5
A22: T7_PC1 | B22: Quanto senti di avere controllo sulle azioni successive (es. contatti, chiusura del caso) partendo dalla dashboard casi di HumanUnity? | C22: FALSE | D22: FALSE | E22: FALSE | F22: FALSE | G22: TRUE | H22: =IF(C22,1,0) + IF(D22,2,0) + IF(E22,3,0) + IF(F22,4,0) + IF(G22,5,0) -> 5
A23: T8_PC1 | B23: Quanto senti di avere controllo su come usare le informazioni aggregate per proporre iniziative di prevenzione nell’ateneo? | C23: FALSE | D23: FALSE | E23: TRUE | F23: FALSE | G23: FALSE | H23: =IF(C23,1,0) + IF(D23,2,0) + IF(E23,3,0) + IF(F23,4,0) + IF(G23,5,0) -> 3
B24: Motivation | C24: FALSE | D24: FALSE | E24: FALSE | F24: FALSE | G24: FALSE | H24: =IF(C24=TRUE,1,0) + IF(D24=TRUE,2,0) + IF(E24=TRUE,3,0) + IF(F24=TRUE,4,0) + IF(G24=TRUE,5,0) -> 0
A25: T1_MOT1 | B25: Quanto ti senti motivato a usare HumanUnity per chiarire se ciò che è successo è una discriminazione? | C25: FALSE | D25: FALSE | E25: FALSE | F25: TRUE | G25: FALSE | H25: =IF(C25,1,0) + IF(D25,2,0) + IF(E25,3,0) + IF(F25,4,0) + IF(G25,5,0) -> 4
A26: T2_MOT1 | B26: Quanto ti senti motivato a consultare la sezione “Cosa posso fare ora” dopo aver riconosciuto un episodio? | C26: FALSE | D26: FALSE | E26: FALSE | F26: TRUE | G26: FALSE | H26: =IF(C26,1,0) + IF(D26,2,0) + IF(E26,3,0) + IF(F26,4,0) + IF(G26,5,0) -> 4
A27: T3_MOT1 | B27: Quanto ti senti motivato a documentare l’episodio subito in HumanUnity, sapendo che potrai rivederlo in seguito? | C27: FALSE | D27: FALSE | E27: FALSE | F27: TRUE | G27: FALSE | H27: =IF(C27,1,0) + IF(D27,2,0) + IF(E27,3,0) + IF(F27,4,0) + IF(G27,5,0) -> 4
A28: T4_MOT1 | B28: Quanto ti senti motivato a inviare una segnalazione tramite HumanUnity invece di non fare nulla? | C28: FALSE | D28: FALSE | E28: FALSE | F28: TRUE | G28: FALSE | H28: =IF(C28,1,0) + IF(D28,2,0) + IF(E28,3,0) + IF(F28,4,0) + IF(G28,5,0) -> 4
A29: T5_MOT1 | B29: Quanto ti senti motivato a usare le informazioni di contatto fornite dal sistema per chiedere aiuto (sportello d’ateneo, UNAR, numeri)? | C29: FALSE | D29: FALSE | E29: FALSE | F29: TRUE | G29: FALSE | H29: =IF(C29,1,0) + IF(D29,2,0) + IF(E29,3,0) + IF(F29,4,0) + IF(G29,5,0) -> 4
A30: T6_MOT1 | B30: Quanto ti senti motivato a usare HumanUnity per sostenere un compagno che ha subito discriminazione? | C30: FALSE | D30: FALSE | E30: TRUE | F30: FALSE | G30: FALSE | H30: =IF(C30,1,0) + IF(D30,2,0) + IF(E30,3,0) + IF(F30,4,0) + IF(G30,5,0) -> 3
A31: T7_MOT1 | B31: Quanto ti senti motivato a controllare periodicamente gli aggiornamenti del tuo caso nella sezione “I tuoi casi”? | C31: FALSE | D31: FALSE | E31: TRUE | F31: FALSE | G31: FALSE | H31: =IF(C31,1,0) + IF(D31,2,0) + IF(E31,3,0) + IF(F31,4,0) + IF(G31,5,0) -> 3
A32: T8_MOT1 | B32: Quanto ti senti motivato a consultare periodicamente i dati aggregati per capire se la situazione nell’ateneo sta migliorando? | C32: FALSE | D32: FALSE | E32: FALSE | F32: TRUE | G32: FALSE | H32: =IF(C32,1,0) + IF(D32,2,0) + IF(E32,3,0) + IF(F32,4,0) + IF(G32,5,0) -> 4

Sheet Quest.Utente4
B1: Self Efficacy | C1: Scarso | D1: Sufficiente | E1: Buono | F1: Molto Buono | G1: Eccellente | H1: Valore
A2: T1_SE1 | B2: Quanto ti senti in grado di usare HumanUnity per riconoscere se un episodio è una possibile discriminazione? | C2: FALSE | D2: FALSE | E2: FALSE | F2: FALSE | G2: TRUE | H2: =IF(C2,1,0) + IF(D2,2,0) + IF(E2,3,0) + IF(F2,4,0) + IF(G2,5,0) -> 5
A3: T2_SE2 | B3: Quanto ti senti capace di seguire i passi immediati suggeriti da HumanUnity dopo un episodio? | C3: FALSE | D3: FALSE | E3: FALSE | F3: TRUE | G3: FALSE | H3: =IF(C3,1,0) + IF(D3,2,0) + IF(E3,3,0) + IF(F3,4,0) + IF(G3,5,0) -> 4
A4: T3_SE1 | B4: Quanto ti senti in grado di documentare in modo chiaro cosa è successo usando HumanUnity (dove, quando, cosa)? | C4: FALSE | D4: FALSE | E4: FALSE | F4: TRUE | G4: FALSE | H4: =IF(C4,1,0) + IF(D4,2,0) + IF(E4,3,0) + IF(F4,4,0) + IF(G4,5,0) -> 4
A5: T4_SE1 | B5: Quanto ti senti in grado di completare una segnalazione (anche anonima) tramite HumanUnity? | C5: FALSE | D5: FALSE | E5: FALSE | F5: TRUE | G5: FALSE | H5: =IF(C5,1,0) + IF(D5,2,0) + IF(E5,3,0) + IF(F5,4,0) + IF(G5,5,0) -> 4
A6: T5_SE1 | B6: Quanto ti senti capace di usare HumanUnity per contattare i referenti o i servizi giusti (sportello, UNAR, ecc.)? | C6: FALSE | D6: FALSE | E6: FALSE | F6: TRUE | G6: FALSE | H6: =IF(C6,1,0) + IF(D6,2,0) + IF(E6,3,0) + IF(F6,4,0) + IF(G6,5,0) -> 4
A7: T6_SE1 | B7: Quanto ti senti in grado di usare HumanUnity per trovare indicazioni su come supportare la persona coinvolta? | C7: FALSE | D7: FALSE | E7: FALSE | F7: TRUE | G7: FALSE | H7: =IF(C7,1,0) + IF(D7,2,0) + IF(E7,3,0) + IF(F7,4,0) + IF(G7,5,0) -> 4
A8: T7_SE1 | B8: Quanto ti senti in grado di seguire il follow-up di un caso e capire a che punto è dalla sezione “I tuoi casi”? | C8: FALSE | D8: FALSE | E8: TRUE | F8: FALSE | G8: FALSE | H8: =IF(C8,1,0) + IF(D8,2,0) + IF(E8,3,0) + IF(F8,4,0) + IF(G8,5,0) -> 3
A9: T8_SE1 | B9: Quanto ti senti capace di capire, tramite HumanUnity, se ci sono pattern ricorrenti di episodi nell’ateneo? | C9: FALSE | D9: FALSE | E9: FALSE | F9: FALSE | G9: TRUE | H9: =IF(C9,1,0) + IF(D9,2,0) + IF(E9,3,0) + IF(F9,4,0) + IF(G9,5,0) -> 5
B10: Knowledge&Skills | C10: FALSE | D10: FALSE | E10: FALSE | F10: FALSE | G10: FALSE | H10: =IF(C10=TRUE,1,0) + IF(D10=TRUE,2,0) + IF(E10=TRUE,3,0) + IF(F10=TRUE,4,0) + IF(G10=TRUE,5,0) -> 0
A11: T1_KS1 | B11: Quanto conosci le categorie di episodio (commenti offensivi, esclusione, minacce…) mostrate da HumanUnity nella fase iniziale? | C11: FALSE | D11: FALSE | E11: FALSE | F11: TRUE | G11: FALSE | H11: =IF(C11,1,0) + IF(D11,2,0) + IF(E11,3,0) + IF(F11,4,0) + IF(G11,5,0) -> 4
A12: T2_KS1 | B12: Quanto ti senti competente nel comprendere i passi immediati consigliati da HumanUnity dopo un episodio? | C12: FALSE | D12: FALSE | E12: FALSE | F12: TRUE | G12: FALSE | H12: =IF(C12,1,0) + IF(D12,2,0) + IF(E12,3,0) + IF(F12,4,0) + IF(G12,5,0) -> 4
A13: T3_KS1 | B13: Quanto conosci quali dettagli inserire nei campi per documentare in sicurezza luogo, data e descrizione dell’episodio? | C13: FALSE | D13: FALSE | E13: FALSE | F13: TRUE | G13: FALSE | H13: =IF(C13,1,0) + IF(D13,2,0) + IF(E13,3,0) + IF(F13,4,0) + IF(G13,5,0) -> 4
A14: T4_KS1 | B14: Quanto ti senti competente nel scegliere tra segnalazione rapida e segnalazione dettagliata in HumanUnity? | C14: FALSE | D14: FALSE | E14: FALSE | F14: TRUE | G14: FALSE | H14: =IF(C14,1,0) + IF(D14,2,0) + IF(E14,3,0) + IF(F14,4,0) + IF(G14,5,0) -> 4
A15: T5_KS1 | B15: Quanto conosci le diverse opzioni di contatto (sportello d’ateneo, UNAR, numeri utili) che il sistema propone? | C15: FALSE | D15: FALSE | E15: TRUE | F15: FALSE | G15: FALSE | H15: =IF(C15,1,0) + IF(D15,2,0) + IF(E15,3,0) + IF(F15,4,0) + IF(G15,5,0) -> 3
A16: T6_KS1 | B16: Quanto conosci le indicazioni pratiche che HumanUnity fornisce per aiutare una persona che subisce discriminazione? | C16: FALSE | D16: FALSE | E16: FALSE | F16: TRUE | G16: FALSE | H16: =IF(C16,1,0) + IF(D16,2,0) + IF(E16,3,0) + IF(F16,4,0) + IF(G16,5,0) -> 4
A17: T7_KS1 | B17: Quanto ti senti competente nel leggere lo stato di un caso (nuovo, in valutazione, chiuso) nella dashboard referenti? | C17: FALSE | D17: FALSE | E17: FALSE | F17: TRUE | G17: FALSE | H17: =IF(C17,1,0) + IF(D17,2,0) + IF(E17,3,0) + IF(F17,4,0) + IF(G17,5,0) -> 4
A18: T8_KS1 | B18: Quanto conosci il significato delle informazioni aggregate che potrebbero essere usate per la prevenzione (es. trend per corso/area)? | C18: FALSE | D18: FALSE | E18: FALSE | F18: TRUE | G18: FALSE | H18: =IF(C18,1,0) + IF(D18,2,0) + IF(E18,3,0) + IF(F18,4,0) + IF(G18,5,0) -> 4
B19: Personal Control | C19: FALSE | D19: FALSE | E19: FALSE | F19: FALSE | G19: FALSE | H19: =IF(C19=TRUE,1,0) + IF(D19=TRUE,2,0) + IF(E19=TRUE,3,0) + IF(F19=TRUE,4,0) + IF(G19=TRUE,5,0) -> 0
A20: T3_PC1 | B20: Quanto senti di avere controllo sul modo in cui i dettagli dell’episodio vengono registrati in HumanUnity? | C20: FALSE | D20: FALSE | E20: TRUE | F20: FALSE | G20: FALSE | H20: =IF(C20,1,0) + IF(D20,2,0) + IF(E20,3,0) + IF(F20,4,0) + IF(G20,5,0) -> 3
A21: T4_PC1 | B21: Quanto senti di poter decidere quali dati inserire e quale livello di anonimato usare nella segnalazione? | C21: FALSE | D21: FALSE | E21: FALSE | F21: TRUE | G21: FALSE | H21: =IF(C21,1,0) + IF(D21,2,0) + IF(E21,3,0) + IF(F21,4,0) + IF(G21,5,0) -> 4
A22: T7_PC1 | B22: Quanto senti di avere controllo sulle azioni successive (es. contatti, chiusura del caso) partendo dalla dashboard casi di HumanUnity? | C22: FALSE | D22: FALSE | E22: FALSE | F22: FALSE | G22: TRUE | H22: =IF(C22,1,0) + IF(D22,2,0) + IF(E22,3,0) + IF(F22,4,0) + IF(G22,5,0) -> 5
A23: T8_PC1 | B23: Quanto senti di avere controllo su come usare le informazioni aggregate per proporre iniziative di prevenzione nell’ateneo? | C23: FALSE | D23: FALSE | E23: FALSE | F23: TRUE | G23: FALSE | H23: =IF(C23,1,0) + IF(D23,2,0) + IF(E23,3,0) + IF(F23,4,0) + IF(G23,5,0) -> 4
B24: Motivation | C24: FALSE | D24: FALSE | E24: FALSE | F24: FALSE | G24: FALSE | H24: =IF(C24=TRUE,1,0) + IF(D24=TRUE,2,0) + IF(E24=TRUE,3,0) + IF(F24=TRUE,4,0) + IF(G24=TRUE,5,0) -> 0
A25: T1_MOT1 | B25: Quanto ti senti motivato a usare HumanUnity per chiarire se ciò che è successo è una discriminazione? | C25: FALSE | D25: FALSE | E25: FALSE | F25: TRUE | G25: FALSE | H25: =IF(C25,1,0) + IF(D25,2,0) + IF(E25,3,0) + IF(F25,4,0) + IF(G25,5,0) -> 4
A26: T2_MOT1 | B26: Quanto ti senti motivato a consultare la sezione “Cosa posso fare ora” dopo aver riconosciuto un episodio? | C26: FALSE | D26: FALSE | E26: FALSE | F26: FALSE | G26: TRUE | H26: =IF(C26,1,0) + IF(D26,2,0) + IF(E26,3,0) + IF(F26,4,0) + IF(G26,5,0) -> 5
A27: T3_MOT1 | B27: Quanto ti senti motivato a documentare l’episodio subito in HumanUnity, sapendo che potrai rivederlo in seguito? | C27: FALSE | D27: FALSE | E27: FALSE | F27: TRUE | G27: FALSE | H27: =IF(C27,1,0) + IF(D27,2,0) + IF(E27,3,0) + IF(F27,4,0) + IF(G27,5,0) -> 4
A28: T4_MOT1 | B28: Quanto ti senti motivato a inviare una segnalazione tramite HumanUnity invece di non fare nulla? | C28: FALSE | D28: FALSE | E28: FALSE | F28: FALSE | G28: TRUE | H28: =IF(C28,1,0) + IF(D28,2,0) + IF(E28,3,0) + IF(F28,4,0) + IF(G28,5,0) -> 5
A29: T5_MOT1 | B29: Quanto ti senti motivato a usare le informazioni di contatto fornite dal sistema per chiedere aiuto (sportello d’ateneo, UNAR, numeri)? | C29: FALSE | D29: FALSE | E29: FALSE | F29: TRUE | G29: FALSE | H29: =IF(C29,1,0) + IF(D29,2,0) + IF(E29,3,0) + IF(F29,4,0) + IF(G29,5,0) -> 4
A30: T6_MOT1 | B30: Quanto ti senti motivato a usare HumanUnity per sostenere un compagno che ha subito discriminazione? | C30: FALSE | D30: FALSE | E30: FALSE | F30: TRUE | G30: FALSE | H30: =IF(C30,1,0) + IF(D30,2,0) + IF(E30,3,0) + IF(F30,4,0) + IF(G30,5,0) -> 4
A31: T7_MOT1 | B31: Quanto ti senti motivato a controllare periodicamente gli aggiornamenti del tuo caso nella sezione “I tuoi casi”? | C31: FALSE | D31: FALSE | E31: FALSE | F31: TRUE | G31: FALSE | H31: =IF(C31,1,0) + IF(D31,2,0) + IF(E31,3,0) + IF(F31,4,0) + IF(G31,5,0) -> 4
A32: T8_MOT1 | B32: Quanto ti senti motivato a consultare periodicamente i dati aggregati per capire se la situazione nell’ateneo sta migliorando? | C32: FALSE | D32: FALSE | E32: FALSE | F32: TRUE | G32: FALSE | H32: =IF(C32,1,0) + IF(D32,2,0) + IF(E32,3,0) + IF(F32,4,0) + IF(G32,5,0) -> 4

Sheet Quest.Utente5
B1: Self Efficacy | C1: Scarso | D1: Sufficiente | E1: Buono | F1: Molto Buono | G1: Eccellente | H1: Valore
A2: T1_SE1 | B2: Quanto ti senti in grado di usare HumanUnity per riconoscere se un episodio è una possibile discriminazione? | C2: FALSE | D2: FALSE | E2: FALSE | F2: TRUE | G2: FALSE | H2: =IF(C2,1,0) + IF(D2,2,0) + IF(E2,3,0) + IF(F2,4,0) + IF(G2,5,0) -> 4
A3: T2_SE2 | B3: Quanto ti senti capace di seguire i passi immediati suggeriti da HumanUnity dopo un episodio? | C3: FALSE | D3: FALSE | E3: FALSE | F3: FALSE | G3: TRUE | H3: =IF(C3,1,0) + IF(D3,2,0) + IF(E3,3,0) + IF(F3,4,0) + IF(G3,5,0) -> 5
A4: T3_SE1 | B4: Quanto ti senti in grado di documentare in modo chiaro cosa è successo usando HumanUnity (dove, quando, cosa)? | C4: FALSE | D4: FALSE | E4: FALSE | F4: TRUE | G4: FALSE | H4: =IF(C4,1,0) + IF(D4,2,0) + IF(E4,3,0) + IF(F4,4,0) + IF(G4,5,0) -> 4
A5: T4_SE1 | B5: Quanto ti senti in grado di completare una segnalazione (anche anonima) tramite HumanUnity? | C5: FALSE | D5: FALSE | E5: FALSE | F5: TRUE | G5: FALSE | H5: =IF(C5,1,0) + IF(D5,2,0) + IF(E5,3,0) + IF(F5,4,0) + IF(G5,5,0) -> 4
A6: T5_SE1 | B6: Quanto ti senti capace di usare HumanUnity per contattare i referenti o i servizi giusti (sportello, UNAR, ecc.)? | C6: FALSE | D6: FALSE | E6: FALSE | F6: TRUE | G6: FALSE | H6: =IF(C6,1,0) + IF(D6,2,0) + IF(E6,3,0) + IF(F6,4,0) + IF(G6,5,0) -> 4
A7: T6_SE1 | B7: Quanto ti senti in grado di usare HumanUnity per trovare indicazioni su come supportare la persona coinvolta? | C7: FALSE | D7: FALSE | E7: FALSE | F7: TRUE | G7: FALSE | H7: =IF(C7,1,0) + IF(D7,2,0) + IF(E7,3,0) + IF(F7,4,0) + IF(G7,5,0) -> 4
A8: T7_SE1 | B8: Quanto ti senti in grado di seguire il follow-up di un caso e capire a che punto è dalla sezione “I tuoi casi”? | C8: FALSE | D8: FALSE | E8: FALSE | F8: TRUE | G8: FALSE | H8: =IF(C8,1,0) + IF(D8,2,0) + IF(E8,3,0) + IF(F8,4,0) + IF(G8,5,0) -> 4
A9: T8_SE1 | B9: Quanto ti senti capace di capire, tramite HumanUnity, se ci sono pattern ricorrenti di episodi nell’ateneo? | C9: FALSE | D9: FALSE | E9: FALSE | F9: TRUE | G9: FALSE | H9: =IF(C9,1,0) + IF(D9,2,0) + IF(E9,3,0) + IF(F9,4,0) + IF(G9,5,0) -> 4
B10: Knowledge&Skills | C10: FALSE | D10: FALSE | E10: FALSE | F10: FALSE | G10: FALSE | H10: =IF(C10=TRUE,1,0) + IF(D10=TRUE,2,0) + IF(E10=TRUE,3,0) + IF(F10=TRUE,4,0) + IF(G10=TRUE,5,0) -> 0
A11: T1_KS1 | B11: Quanto conosci le categorie di episodio (commenti offensivi, esclusione, minacce…) mostrate da HumanUnity nella fase iniziale? | C11: FALSE | D11: FALSE | E11: FALSE | F11: TRUE | G11: FALSE | H11: =IF(C11,1,0) + IF(D11,2,0) + IF(E11,3,0) + IF(F11,4,0) + IF(G11,5,0) -> 4
A12: T2_KS1 | B12: Quanto ti senti competente nel comprendere i passi immediati consigliati da HumanUnity dopo un episodio? | C12: FALSE | D12: TRUE | E12: FALSE | F12: FALSE | G12: FALSE | H12: =IF(C12,1,0) + IF(D12,2,0) + IF(E12,3,0) + IF(F12,4,0) + IF(G12,5,0) -> 2
A13: T3_KS1 | B13: Quanto conosci quali dettagli inserire nei campi per documentare in sicurezza luogo, data e descrizione dell’episodio? | C13: FALSE | D13: FALSE | E13: FALSE | F13: TRUE | G13: FALSE | H13: =IF(C13,1,0) + IF(D13,2,0) + IF(E13,3,0) + IF(F13,4,0) + IF(G13,5,0) -> 4
A14: T4_KS1 | B14: Quanto ti senti competente nel scegliere tra segnalazione rapida e segnalazione dettagliata in HumanUnity? | C14: FALSE | D14: FALSE | E14: FALSE | F14: TRUE | G14: FALSE | H14: =IF(C14,1,0) + IF(D14,2,0) + IF(E14,3,0) + IF(F14,4,0) + IF(G14,5,0) -> 4
A15: T5_KS1 | B15: Quanto conosci le diverse opzioni di contatto (sportello d’ateneo, UNAR, numeri utili) che il sistema propone? | C15: FALSE | D15: FALSE | E15: FALSE | F15: TRUE | G15: FALSE | H15: =IF(C15,1,0) + IF(D15,2,0) + IF(E15,3,0) + IF(F15,4,0) + IF(G15,5,0) -> 4
A16: T6_KS1 | B16: Quanto conosci le indicazioni pratiche che HumanUnity fornisce per aiutare una persona che subisce discriminazione? | C16: FALSE | D16: FALSE | E16: FALSE | F16: TRUE | G16: FALSE | H16: =IF(C16,1,0) + IF(D16,2,0) + IF(E16,3,0) + IF(F16,4,0) + IF(G16,5,0) -> 4
A17: T7_KS1 | B17: Quanto ti senti competente nel leggere lo stato di un caso (nuovo, in valutazione, chiuso) nella dashboard referenti? | C17: FALSE | D17: FALSE | E17: FALSE | F17: TRUE | G17: FALSE | H17: =IF(C17,1,0) + IF(D17,2,0) + IF(E17,3,0) + IF(F17,4,0) + IF(G17,5,0) -> 4
A18: T8_KS1 | B18: Quanto conosci il significato delle informazioni aggregate che potrebbero essere usate per la prevenzione (es. trend per corso/area)? | C18: FALSE | D18: FALSE | E18: FALSE | F18: TRUE | G18: FALSE | H18: =IF(C18,1,0) + IF(D18,2,0) + IF(E18,3,0) + IF(F18,4,0) + IF(G18,5,0) -> 4
B19: Personal Control | C19: FALSE | D19: FALSE | E19: FALSE | F19: FALSE | G19: FALSE | H19: =IF(C19=TRUE,1,0) + IF(D19=TRUE,2,0) + IF(E19=TRUE,3,0) + IF(F19=TRUE,4,0) + IF(G19=TRUE,5,0) -> 0
A20: T3_PC1 | B20: Quanto senti di avere controllo sul modo in cui i dettagli dell’episodio vengono registrati in HumanUnity? | C20: FALSE | D20: FALSE | E20: TRUE | F20: FALSE | G20: FALSE | H20: =IF(C20,1,0) + IF(D20,2,0) + IF(E20,3,0) + IF(F20,4,0) + IF(G20,5,0) -> 3
A21: T4_PC1 | B21: Quanto senti di poter decidere quali dati inserire e quale livello di anonimato usare nella segnalazione? | C21: FALSE | D21: FALSE | E21: TRUE | F21: FALSE | G21: FALSE | H21: =IF(C21,1,0) + IF(D21,2,0) + IF(E21,3,0) + IF(F21,4,0) + IF(G21,5,0) -> 3
A22: T7_PC1 | B22: Quanto senti di avere controllo sulle azioni successive (es. contatti, chiusura del caso) partendo dalla dashboard casi di HumanUnity? | C22: FALSE | D22: FALSE | E22: FALSE | F22: TRUE | G22: FALSE | H22: =IF(C22,1,0) + IF(D22,2,0) + IF(E22,3,0) + IF(F22,4,0) + IF(G22,5,0) -> 4
A23: T8_PC1 | B23: Quanto senti di avere controllo su come usare le informazioni aggregate per proporre iniziative di prevenzione nell’ateneo? | C23: FALSE | D23: FALSE | E23: TRUE | F23: FALSE | G23: FALSE | H23: =IF(C23,1,0) + IF(D23,2,0) + IF(E23,3,0) + IF(F23,4,0) + IF(G23,5,0) -> 3
B24: Motivation | C24: FALSE | D24: FALSE | E24: FALSE | F24: FALSE | G24: FALSE | H24: =IF(C24=TRUE,1,0) + IF(D24=TRUE,2,0) + IF(E24=TRUE,3,0) + IF(F24=TRUE,4,0) + IF(G24=TRUE,5,0) -> 0
A25: T1_MOT1 | B25: Quanto ti senti motivato a usare HumanUnity per chiarire se ciò che è successo è una discriminazione? | C25: FALSE | D25: FALSE | E25: FALSE | F25: TRUE | G25: FALSE | H25: =IF(C25,1,0) + IF(D25,2,0) + IF(E25,3,0) + IF(F25,4,0) + IF(G25,5,0) -> 4
A26: T2_MOT1 | B26: Quanto ti senti motivato a consultare la sezione “Cosa posso fare ora” dopo aver riconosciuto un episodio? | C26: FALSE | D26: FALSE | E26: FALSE | F26: TRUE | G26: FALSE | H26: =IF(C26,1,0) + IF(D26,2,0) + IF(E26,3,0) + IF(F26,4,0) + IF(G26,5,0) -> 4
A27: T3_MOT1 | B27: Quanto ti senti motivato a documentare l’episodio subito in HumanUnity, sapendo che potrai rivederlo in seguito? | C27: FALSE | D27: FALSE | E27: FALSE | F27: TRUE | G27: FALSE | H27: =IF(C27,1,0) + IF(D27,2,0) + IF(E27,3,0) + IF(F27,4,0) + IF(G27,5,0) -> 4
A28: T4_MOT1 | B28: Quanto ti senti motivato a inviare una segnalazione tramite HumanUnity invece di non fare nulla? | C28: FALSE | D28: TRUE | E28: FALSE | F28: FALSE | G28: FALSE | H28: =IF(C28,1,0) + IF(D28,2,0) + IF(E28,3,0) + IF(F28,4,0) + IF(G28,5,0) -> 2
A29: T5_MOT1 | B29: Quanto ti senti motivato a usare le informazioni di contatto fornite dal sistema per chiedere aiuto (sportello d’ateneo, UNAR, numeri)? | C29: FALSE | D29: FALSE | E29: TRUE | F29: FALSE | G29: FALSE | H29: =IF(C29,1,0) + IF(D29,2,0) + IF(E29,3,0) + IF(F29,4,0) + IF(G29,5,0) -> 3
A30: T6_MOT1 | B30: Quanto ti senti motivato a usare HumanUnity per sostenere un compagno che ha subito discriminazione? | C30: FALSE | D30: FALSE | E30: FALSE | F30: TRUE | G30: FALSE | H30: =IF(C30,1,0) + IF(D30,2,0) + IF(E30,3,0) + IF(F30,4,0) + IF(G30,5,0) -> 4
A31: T7_MOT1 | B31: Quanto ti senti motivato a controllare periodicamente gli aggiornamenti del tuo caso nella sezione “I tuoi casi”? | C31: FALSE | D31: FALSE | E31: FALSE | F31: TRUE | G31: FALSE | H31: =IF(C31,1,0) + IF(D31,2,0) + IF(E31,3,0) + IF(F31,4,0) + IF(G31,5,0) -> 4
A32: T8_MOT1 | B32: Quanto ti senti motivato a consultare periodicamente i dati aggregati per capire se la situazione nell’ateneo sta migliorando? | C32: FALSE | D32: FALSE | E32: FALSE | F32: TRUE | G32: FALSE | H32: =IF(C32,1,0) + IF(D32,2,0) + IF(E32,3,0) + IF(F32,4,0) + IF(G32,5,0) -> 4

Sheet Quest.Utente6
B1: Self Efficacy | C1: Scarso | D1: Sufficiente | E1: Buono | F1: Molto Buono | G1: Eccellente | H1: Valore
A2: T1_SE1 | B2: Quanto ti senti in grado di usare HumanUnity per riconoscere se un episodio è una possibile discriminazione? | C2: FALSE | D2: FALSE | E2: FALSE | F2: TRUE | G2: FALSE | H2: =IF(C2,1,0) + IF(D2,2,0) + IF(E2,3,0) + IF(F2,4,0) + IF(G2,5,0) -> 4
A3: T2_SE2 | B3: Quanto ti senti capace di seguire i passi immediati suggeriti da HumanUnity dopo un episodio? | C3: FALSE | D3: FALSE | E3: FALSE | F3: TRUE | G3: FALSE | H3: =IF(C3,1,0) + IF(D3,2,0) + IF(E3,3,0) + IF(F3,4,0) + IF(G3,5,0) -> 4
A4: T3_SE1 | B4: Quanto ti senti in grado di documentare in modo chiaro cosa è successo usando HumanUnity (dove, quando, cosa)? | C4: FALSE | D4: FALSE | E4: FALSE | F4: TRUE | G4: FALSE | H4: =IF(C4,1,0) + IF(D4,2,0) + IF(E4,3,0) + IF(F4,4,0) + IF(G4,5,0) -> 4
A5: T4_SE1 | B5: Quanto ti senti in grado di completare una segnalazione (anche anonima) tramite HumanUnity? | C5: FALSE | D5: FALSE | E5: FALSE | F5: TRUE | G5: FALSE | H5: =IF(C5,1,0) + IF(D5,2,0) + IF(E5,3,0) + IF(F5,4,0) + IF(G5,5,0) -> 4
A6: T5_SE1 | B6: Quanto ti senti capace di usare HumanUnity per contattare i referenti o i servizi giusti (sportello, UNAR, ecc.)? | C6: FALSE | D6: FALSE | E6: FALSE | F6: TRUE | G6: FALSE | H6: =IF(C6,1,0) + IF(D6,2,0) + IF(E6,3,0) + IF(F6,4,0) + IF(G6,5,0) -> 4
A7: T6_SE1 | B7: Quanto ti senti in grado di usare HumanUnity per trovare indicazioni su come supportare la persona coinvolta? | C7: FALSE | D7: FALSE | E7: FALSE | F7: TRUE | G7: FALSE | H7: =IF(C7,1,0) + IF(D7,2,0) + IF(E7,3,0) + IF(F7,4,0) + IF(G7,5,0) -> 4
A8: T7_SE1 | B8: Quanto ti senti in grado di seguire il follow-up di un caso e capire a che punto è dalla sezione “I tuoi casi”? | C8: FALSE | D8: FALSE | E8: FALSE | F8: FALSE | G8: TRUE | H8: =IF(C8,1,0) + IF(D8,2,0) + IF(E8,3,0) + IF(F8,4,0) + IF(G8,5,0) -> 5
A9: T8_SE1 | B9: Quanto ti senti capace di capire, tramite HumanUnity, se ci sono pattern ricorrenti di episodi nell’ateneo? | C9: FALSE | D9: FALSE | E9: FALSE | F9: TRUE | G9: FALSE | H9: =IF(C9,1,0) + IF(D9,2,0) + IF(E9,3,0) + IF(F9,4,0) + IF(G9,5,0) -> 4
B10: Knowledge&Skills | C10: FALSE | D10: FALSE | E10: FALSE | F10: FALSE | G10: FALSE | H10: =IF(C10=TRUE,1,0) + IF(D10=TRUE,2,0) + IF(E10=TRUE,3,0) + IF(F10=TRUE,4,0) + IF(G10=TRUE,5,0) -> 0
A11: T1_KS1 | B11: Quanto conosci le categorie di episodio (commenti offensivi, esclusione, minacce…) mostrate da HumanUnity nella fase iniziale? | C11: FALSE | D11: FALSE | E11: FALSE | F11: FALSE | G11: TRUE | H11: =IF(C11,1,0) + IF(D11,2,0) + IF(E11,3,0) + IF(F11,4,0) + IF(G11,5,0) -> 5
A12: T2_KS1 | B12: Quanto ti senti competente nel comprendere i passi immediati consigliati da HumanUnity dopo un episodio? | C12: FALSE | D12: FALSE | E12: FALSE | F12: FALSE | G12: TRUE | H12: =IF(C12,1,0) + IF(D12,2,0) + IF(E12,3,0) + IF(F12,4,0) + IF(G12,5,0) -> 5
A13: T3_KS1 | B13: Quanto conosci quali dettagli inserire nei campi per documentare in sicurezza luogo, data e descrizione dell’episodio? | C13: FALSE | D13: FALSE | E13: TRUE | F13: FALSE | G13: FALSE | H13: =IF(C13,1,0) + IF(D13,2,0) + IF(E13,3,0) + IF(F13,4,0) + IF(G13,5,0) -> 3
A14: T4_KS1 | B14: Quanto ti senti competente nel scegliere tra segnalazione rapida e segnalazione dettagliata in HumanUnity? | C14: FALSE | D14: FALSE | E14: FALSE | F14: FALSE | G14: TRUE | H14: =IF(C14,1,0) + IF(D14,2,0) + IF(E14,3,0) + IF(F14,4,0) + IF(G14,5,0) -> 5
A15: T5_KS1 | B15: Quanto conosci le diverse opzioni di contatto (sportello d’ateneo, UNAR, numeri utili) che il sistema propone? | C15: FALSE | D15: FALSE | E15: FALSE | F15: TRUE | G15: FALSE | H15: =IF(C15,1,0) + IF(D15,2,0) + IF(E15,3,0) + IF(F15,4,0) + IF(G15,5,0) -> 4
A16: T6_KS1 | B16: Quanto conosci le indicazioni pratiche che HumanUnity fornisce per aiutare una persona che subisce discriminazione? | C16: FALSE | D16: TRUE | E16: FALSE | F16: FALSE | G16: FALSE | H16: =IF(C16,1,0) + IF(D16,2,0) + IF(E16,3,0) + IF(F16,4,0) + IF(G16,5,0) -> 2
A17: T7_KS1 | B17: Quanto ti senti competente nel leggere lo stato di un caso (nuovo, in valutazione, chiuso) nella dashboard referenti? | C17: FALSE | D17: FALSE | E17: TRUE | F17: FALSE | G17: FALSE | H17: =IF(C17,1,0) + IF(D17,2,0) + IF(E17,3,0) + IF(F17,4,0) + IF(G17,5,0) -> 3
A18: T8_KS1 | B18: Quanto conosci il significato delle informazioni aggregate che potrebbero essere usate per la prevenzione (es. trend per corso/area)? | C18: FALSE | D18: FALSE | E18: FALSE | F18: FALSE | G18: TRUE | H18: =IF(C18,1,0) + IF(D18,2,0) + IF(E18,3,0) + IF(F18,4,0) + IF(G18,5,0) -> 5
B19: Personal Control | C19: FALSE | D19: FALSE | E19: FALSE | F19: FALSE | G19: FALSE | H19: =IF(C19=TRUE,1,0) + IF(D19=TRUE,2,0) + IF(E19=TRUE,3,0) + IF(F19=TRUE,4,0) + IF(G19=TRUE,5,0) -> 0
A20: T3_PC1 | B20: Quanto senti di avere controllo sul modo in cui i dettagli dell’episodio vengono registrati in HumanUnity? | C20: FALSE | D20: FALSE | E20: FALSE | F20: FALSE | G20: TRUE | H20: =IF(C20,1,0) + IF(D20,2,0) + IF(E20,3,0) + IF(F20,4,0) + IF(G20,5,0) -> 5
A21: T4_PC1 | B21: Quanto senti di poter decidere quali dati inserire e quale livello di anonimato usare nella segnalazione? | C21: FALSE | D21: FALSE | E21: TRUE | F21: FALSE | G21: FALSE | H21: =IF(C21,1,0) + IF(D21,2,0) + IF(E21,3,0) + IF(F21,4,0) + IF(G21,5,0) -> 3
A22: T7_PC1 | B22: Quanto senti di avere controllo sulle azioni successive (es. contatti, chiusura del caso) partendo dalla dashboard casi di HumanUnity? | C22: FALSE | D22: FALSE | E22: TRUE | F22: FALSE | G22: FALSE | H22: =IF(C22,1,0) + IF(D22,2,0) + IF(E22,3,0) + IF(F22,4,0) + IF(G22,5,0) -> 3
A23: T8_PC1 | B23: Quanto senti di avere controllo su come usare le informazioni aggregate per proporre iniziative di prevenzione nell’ateneo? | C23: FALSE | D23: FALSE | E23: TRUE | F23: FALSE | G23: FALSE | H23: =IF(C23,1,0) + IF(D23,2,0) + IF(E23,3,0) + IF(F23,4,0) + IF(G23,5,0) -> 3
B24: Motivation | C24: FALSE | D24: FALSE | E24: FALSE | F24: FALSE | G24: FALSE | H24: =IF(C24=TRUE,1,0) + IF(D24=TRUE,2,0) + IF(E24=TRUE,3,0) + IF(F24=TRUE,4,0) + IF(G24=TRUE,5,0) -> 0
A25: T1_MOT1 | B25: Quanto ti senti motivato a usare HumanUnity per chiarire se ciò che è successo è una discriminazione? | C25: FALSE | D25: FALSE | E25: FALSE | F25: TRUE | G25: FALSE | H25: =IF(C25,1,0) + IF(D25,2,0) + IF(E25,3,0) + IF(F25,4,0) + IF(G25,5,0) -> 4
A26: T2_MOT1 | B26: Quanto ti senti motivato a consultare la sezione “Cosa posso fare ora” dopo aver riconosciuto un episodio? | C26: FALSE | D26: FALSE | E26: FALSE | F26: FALSE | G26: TRUE | H26: =IF(C26,1,0) + IF(D26,2,0) + IF(E26,3,0) + IF(F26,4,0) + IF(G26,5,0) -> 5
